Workbook

Sheet 주간 입력
B1: 미식가의 주방 — 주간 정산 입력
B2: 🟡 노란 칸에만 입력하세요 | 3주차=공과금 | 4주차=임대료+관리비 자동
B4: 📋 주간 정산 입력 #1
B5: 월 | D5: ← 1~12
B6: 주차 | D6: ← 1~5
B7: 시작일
B8: 종료일
B9: ■ 매출
B10: 카드매출 | D10: 원
B11: 현금매출 | D11: 원
B12: ■ 공과금 (3주차에 지난달분 입력)
B13: 전기요금 | D13: 원 (고지서 그대로)
B14: 가스요금
B15: 수도요금
B16: ■ 기타 (발생할 때만)
B17: 정화조 청소
B18: 회식 연계매출 | D18: 원 (재생전골 등)
B19: 기타비용
B20: 비고
B22: 📋 주간 정산 입력 #2
B23: 월 | D23: ← 1~12
B24: 주차 | D24: ← 1~5
B25: 시작일
B26: 종료일
B27: ■ 매출
B28: 카드매출 | D28: 원
B29: 현금매출 | D29: 원
B30: ■ 공과금 (3주차에 지난달분 입력)
B31: 전기요금 | D31: 원 (고지서 그대로)
B32: 가스요금
B33: 수도요금
B34: ■ 기타 (발생할 때만)
B35: 정화조 청소
B36: 회식 연계매출 | D36: 원 (재생전골 등)
B37: 기타비용
B38: 비고
B40: 📋 주간 정산 입력 #3
B41: 월 | D41: ← 1~12
B42: 주차 | D42: ← 1~5
B43: 시작일
...

Sheet 대시보드
A1: 미식가의 주방 — 경영 대시보드 (2026년)
M2: 현재월 → | N2: 3
B3: 이번달 총매출 | E3: 이번달 수수료수익 | H3: 이번달 임대수익 | K3: 연간 누적매출
B4: =INDEX(D9:D20,N2) | E4: =INDEX(G9:G20,N2) | H4: =INDEX(H9:H20,N2)+INDEX(I9:I20,N2) | K4: =D21
A7: 📊 월별 정산 요약
A8: 월 | B8: 카드매출 | C8: 현금매출 | D8: 총매출 | E8: 카드수수료 | F8: 현금수수료 | G8: 수수료합계 | H8: 임대료 | I8: 관리비 | J8: 공과금 | K8: 총차감 | L8: 미식가지급 | M8: 현금수령
A9: 1월 | B9: ='정산 요약'!E9 | C9: ='정산 요약'!F9 | D9: ='정산 요약'!G9 | E9: ='정산 요약'!H9 | F9: ='정산 요약'!I9 | G9: ='정산 요약'!J9 | H9: ='정산 요약'!L9 | I9: ='정산 요약'!N9 | J9: ='정산 요약'!O9 | K9: ='정산 요약'!Q9 | L9: ='정산 요약'!R9 | M9: ='정산 요약'!S9
A10: 2월 | B10: ='정산 요약'!E15 | C10: ='정산 요약'!F15 | D10: ='정산 요약'!G15 | E10: ='정산 요약'!H15 | F10: ='정산 요약'!I15 | G10: ='정산 요약'!J15 | H10: ='정산 요약'!L15 | I10: ='정산 요약'!N15 | J10: ='정산 요약'!O15 | K10: ='정산 요약'!Q15 | L10: ='정산 요약'!R15 | M10: ='정산 요약'!S15
A11: 3월 | B11: ='정산 요약'!E21 | C11: ='정산 요약'!F21 | D11: ='정산 요약'!G21 | E11: ='정산 요약'!H21 | F11: ='정산 요약'!I21 | G11: ='정산 요약'!J21 | H11: ='정산 요약'!L21 | I11: ='정산 요약'!N21 | J11: ='정산 요약'!O21 | K11: ='정산 요약'!Q21 | L11: ='정산 요약'!R21 | M11: ='정산 요약'!S21
A12: 4월 | B12: ='정산 요약'!E27 | C12: ='정산 요약'!F27 | D12: ='정산 요약'!G27 | E12: ='정산 요약'!H27 | F12: ='정산 요약'!I27 | G12: ='정산 요약'!J27 | H12: ='정산 요약'!L27 | I12: ='정산 요약'!N27 | J12: ='정산 요약'!O27 | K12: ='정산 요약'!Q27 | L12: ='정산 요약'!R27 | M12: ='정산 요약'!S27
A13: 5월 | B13: ='정산 요약'!E33 | C13: ='정산 요약'!F33 | D13: ='정산 요약'!G33 | E13: ='정산 요약'!H33 | F13: ='정산 요약'!I33 | G13: ='정산 요약'!J33 | H13: ='정산 요약'!L33 | I13: ='정산 요약'!N33 | J13: ='정산 요약'!O33 | K13: ='정산 요약'!Q33 | L13: ='정산 요약'!R33 | M13: ='정산 요약'!S33
A14: 6월 | B14: ='정산 요약'!E39 | C14: ='정산 요약'!F39 | D14: ='정산 요약'!G39 | E14: ='정산 요약'!H39 | F14: ='정산 요약'!I39 | G14: ='정산 요약'!J39 | H14: ='정산 요약'!L39 | I14: ='정산 요약'!N39 | J14: ='정산 요약'!O39 | K14: ='정산 요약'!Q39 | L14: ='정산 요약'!R39 | M14: ='정산 요약'!S39
A15: 7월 | B15: ='정산 요약'!E45 | C15: ='정산 요약'!F45 | D15: ='정산 요약'!G45 | E15: ='정산 요약'!H45 | F15: ='정산 요약'!I45 | G15: ='정산 요약'!J45 | H15: ='정산 요약'!L45 | I15: ='정산 요약'!N45 | J15: ='정산 요약'!O45 | K15: ='정산 요약'!Q45 | L15: ='정산 요약'!R45 | M15: ='정산 요약'!S45
A16: 8월 | B16: ='정산 요약'!E51 | C16: ='정산 요약'!F51 | D16: ='정산 요약'!G51 | E16: ='정산 요약'!H51 | F16: ='정산 요약'!I51 | G16: ='정산 요약'!J51 | H16: ='정산 요약'!L51 | I16: ='정산 요약'!N51 | J16: ='정산 요약'!O51 | K16: ='정산 요약'!Q51 | L16: ='정산 요약'!R51 | M16: ='정산 요약'!S51
A17: 9월 | B17: ='정산 요약'!E57 | C17: ='정산 요약'!F57 | D17: ='정산 요약'!G57 | E17: ='정산 요약'!H57 | F17: ='정산 요약'!I57 | G17: ='정산 요약'!J57 | H17: ='정산 요약'!L57 | I17: ='정산 요약'!N57 | J17: ='정산 요약'!O57 | K17: ='정산 요약'!Q57 | L17: ='정산 요약'!R57 | M17: ='정산 요약'!S57
A18: 10월 | B18: ='정산 요약'!E63 | C18: ='정산 요약'!F63 | D18: ='정산 요약'!G63 | E18: ='정산 요약'!H63 | F18: ='정산 요약'!I63 | G18: ='정산 요약'!J63 | H18: ='정산 요약'!L63 | I18: ='정산 요약'!N63 | J18: ='정산 요약'!O63 | K18: ='정산 요약'!Q63 | L18: ='정산 요약'!R63 | M18: ='정산 요약'!S63
A19: 11월 | B19: ='정산 요약'!E69 | C19: ='정산 요약'!F69 | D19: ='정산 요약'!G69 | E19: ='정산 요약'!H69 | F19: ='정산 요약'!I69 | G19: ='정산 요약'!J69 | H19: ='정산 요약'!L69 | I19: ='정산 요약'!N69 | J19: ='정산 요약'!O69 | K19: ='정산 요약'!Q69 | L19: ='정산 요약'!R69 | M19: ='정산 요약'!S69
A20: 12월 | B20: ='정산 요약'!E75 | C20: ='정산 요약'!F75 | D20: ='정산 요약'!G75 | E20: ='정산 요약'!H75 | F20: ='정산 요약'!I75 | G20: ='정산 요약'!J75 | H20: ='정산 요약'!L75 | I20: ='정산 요약'!N75 | J20: ='정산 요약'!O75 | K20: ='정산 요약'!Q75 | L20: ='정산 요약'!R75 | M20: ='정산 요약'!S75
A21: 합계 | B21: =SUM(B9:B20) | C21: =SUM(C9:C20) | D21: =SUM(D9:D20) | E21: =SUM(E9:E20) | F21: =SUM(F9:F20) | G21: =SUM(G9:G20) | H21: =SUM(H9:H20) | I21: =SUM(I9:I20) | ... M21: =SUM(M9:M20)
A40: 수익 구성 데이터
A41: 카드수수료 | B41: =E21
A42: 현금수수료 | B42: =F21
A43: 임대료 | B43: =H21
A44: 관리비 | B44: =I21
A45: 공과금 | B45: =J21

Sheet 정산 요약
A1: 미식가의 주방 — 주간 정산 요약 (2026년)
A2: ⬜ 전체 자동 — 시트1 입력 → 여기서 정산 계산 | 3주차=공과금 / 4주차=임대료+관리비
A3: 월 | B3: 주 | C3: 시작일 | D3: 종료일 | E3: 카드매출 | F3: 현금매출 | G3: 총매출 | H3: 카드수수료 (15%) | I3: 현금수수료 (13%) | J3: 수수료합계 | K3: 수수료 VAT | L3: 임대료 | M3: 임대료 VAT | N3: 관리비+ 고정비 | O3: 공과금 (95%) | P3: 기타비용 | Q3: 총 차감액 | R3: 미식가 카드지급 | S3: 현금 수령액 | T3: 비고
A4: ='주간 입력'!C5 | B4: ='주간 입력'!C6 | C4: ='주간 입력'!C7 | D4: ='주간 입력'!C8 | E4: ='주간 입력'!C10 | F4: ='주간 입력'!C11 | G4: =IF(E4="","",E4+F4) | H4: =IF(E4="","",E4*0.15) | I4: =IF(E4="","",IF(F4="",0,F4*0.13)) | J4: =IF(E4="","",H4+I4) | K4: =IF(E4="","",J4*0.1) | L4: =IF('주간 입력'!C6=4,3000000,0) | M4: =IF(L4=0,0,L4*0.1) | N4: =IF('주간 입력'!C6=4,55000+15900+50000,0) | O4: =(IF('주간 입력'!C13="",0,'주간 입력'!C13)+IF('주간 입력'!C14="",0,'주간 입력'!C14)+IF('주간 입력'!C15="",0,'주간 입력'!C15))*0.95 | P4: =IF('주간 입력'!C17="",0,'주간 입력'!C17)+IF('주간 입력'!C18="",0,'주간 입력'!C18*0.05)+IF('주간 입력'!C19="",0,'주간 입력'!C19) | Q4: =IF(E4="","",J4+K4+L4+M4+N4+O4+P4) | R4: =IF(E4="","",E4-Q4) | S4: =IF(E4="","",F4-I4-I4*0.1) | T4: ='주간 입력'!C20
A5: ='주간 입력'!C23 | B5: ='주간 입력'!C24 | C5: ='주간 입력'!C25 | D5: ='주간 입력'!C26 | E5: ='주간 입력'!C28 | F5: ='주간 입력'!C29 | G5: =IF(E5="","",E5+F5) | H5: =IF(E5="","",E5*0.15) | I5: =IF(E5="","",IF(F5="",0,F5*0.13)) | J5: =IF(E5="","",H5+I5) | K5: =IF(E5="","",J5*0.1) | L5: =IF('주간 입력'!C24=4,3000000,0) | M5: =IF(L5=0,0,L5*0.1) | N5: =IF('주간 입력'!C24=4,55000+15900+50000,0) | O5: =(IF('주간 입력'!C31="",0,'주간 입력'!C31)+IF('주간 입력'!C32="",0,'주간 입력'!C32)+IF('주간 입력'!C33="",0,'주간 입력'!C33))*0.95 | P5: =IF('주간 입력'!C35="",0,'주간 입력'!C35)+IF('주간 입력'!C36="",0,'주간 입력'!C36*0.05)+IF('주간 입력'!C37="",0,'주간 입력'!C37) | Q5: =IF(E5="","",J5+K5+L5+M5+N5+O5+P5) | R5: =IF(E5="","",E5-Q5) | S5: =IF(E5="","",F5-I5-I5*0.1) | T5: ='주간 입력'!C38
A6: ='주간 입력'!C41 | B6: ='주간 입력'!C42 | C6: ='주간 입력'!C43 | D6: ='주간 입력'!C44 | E6: ='주간 입력'!C46 | F6: ='주간 입력'!C47 | G6: =IF(E6="","",E6+F6) | H6: =IF(E6="","",E6*0.15) | I6: =IF(E6="","",IF(F6="",0,F6*0.13)) | J6: =IF(E6="","",H6+I6) | K6: =IF(E6="","",J6*0.1) | L6: =IF('주간 입력'!C42=4,3000000,0) | M6: =IF(L6=0,0,L6*0.1) | N6: =IF('주간 입력'!C42=4,55000+15900+50000,0) | O6: =(IF('주간 입력'!C49="",0,'주간 입력'!C49)+IF('주간 입력'!C50="",0,'주간 입력'!C50)+IF('주간 입력'!C51="",0,'주간 입력'!C51))*0.95 | P6: =IF('주간 입력'!C53="",0,'주간 입력'!C53)+IF('주간 입력'!C54="",0,'주간 입력'!C54*0.05)+IF('주간 입력'!C55="",0,'주간 입력'!C55) | Q6: =IF(E6="","",J6+K6+L6+M6+N6+O6+P6) | R6: =IF(E6="","",E6-Q6) | S6: =IF(E6="","",F6-I6-I6*0.1) | T6: ='주간 입력'!C56
A7: ='주간 입력'!C59 | B7: ='주간 입력'!C60 | C7: ='주간 입력'!C61 | D7: ='주간 입력'!C62 | E7: ='주간 입력'!C64 | F7: ='주간 입력'!C65 | G7: =IF(E7="","",E7+F7) | H7: =IF(E7="","",E7*0.15) | I7: =IF(E7="","",IF(F7="",0,F7*0.13)) | J7: =IF(E7="","",H7+I7) | K7: =IF(E7="","",J7*0.1) | L7: =IF('주간 입력'!C60=4,3000000,0) | M7: =IF(L7=0,0,L7*0.1) | N7: =IF('주간 입력'!C60=4,55000+15900+50000,0) | O7: =(IF('주간 입력'!C67="",0,'주간 입력'!C67)+IF('주간 입력'!C68="",0,'주간 입력'!C68)+IF('주간 입력'!C69="",0,'주간 입력'!C69))*0.95 | P7: =IF('주간 입력'!C71="",0,'주간 입력'!C71)+IF('주간 입력'!C72="",0,'주간 입력'!C72*0.05)+IF('주간 입력'!C73="",0,'주간 입력'!C73) | Q7: =IF(E7="","",J7+K7+L7+M7+N7+O7+P7) | R7: =IF(E7="","",E7-Q7) | S7: =IF(E7="","",F7-I7-I7*0.1) | T7: ='주간 입력'!C74
A8: ='주간 입력'!C77 | B8: ='주간 입력'!C78 | C8: ='주간 입력'!C79 | D8: ='주간 입력'!C80 | E8: ='주간 입력'!C82 | F8: ='주간 입력'!C83 | G8: =IF(E8="","",E8+F8) | H8: =IF(E8="","",E8*0.15) | I8: =IF(E8="","",IF(F8="",0,F8*0.13)) | J8: =IF(E8="","",H8+I8) | K8: =IF(E8="","",J8*0.1) | L8: =IF('주간 입력'!C78=4,3000000,0) | M8: =IF(L8=0,0,L8*0.1) | N8: =IF('주간 입력'!C78=4,55000+15900+50000,0) | O8: =(IF('주간 입력'!C85="",0,'주간 입력'!C85)+IF('주간 입력'!C86="",0,'주간 입력'!C86)+IF('주간 입력'!C87="",0,'주간 입력'!C87))*0.95 | P8: =IF('주간 입력'!C89="",0,'주간 입력'!C89)+IF('주간 입력'!C90="",0,'주간 입력'!C90*0.05)+IF('주간 입력'!C91="",0,'주간 입력'!C91) | Q8: =IF(E8="","",J8+K8+L8+M8+N8+O8+P8) | R8: =IF(E8="","",E8-Q8) | S8: =IF(E8="","",F8-I8-I8*0.1) | T8: ='주간 입력'!C92
A9: 1월 | B9: 소계 | E9: =SUM(E4:E8) | F9: =SUM(F4:F8) | G9: =SUM(G4:G8) | H9: =SUM(H4:H8) | I9: =SUM(I4:I8) | J9: =SUM(J4:J8) | K9: =SUM(K4:K8) | L9: =SUM(L4:L8) | ... S9: =SUM(S4:S8)
A10: ='주간 입력'!C95 | B10: ='주간 입력'!C96 | C10: ='주간 입력'!C97 | D10: ='주간 입력'!C98 | E10: ='주간 입력'!C100 | F10: ='주간 입력'!C101 | G10: =IF(E10="","",E10+F10) | H10: =IF(E10="","",E10*0.15) | I10: =IF(E10="","",IF(F10="",0,F10*0.13)) | J10: =IF(E10="","",H10+I10) | K10: =IF(E10="","",J10*0.1) | L10: =IF('주간 입력'!C96=4,3000000,0) | M10: =IF(L10=0,0,L10*0.1) | N10: =IF('주간 입력'!C96=4,55000+15900+50000,0) | O10: =(IF('주간 입력'!C103="",0,'주간 입력'!C103)+IF('주간 입력'!C104="",0,'주간 입력'!C104)+IF('주간 입력'!C105="",0,'주간 입력'!C105))*0.95 | P10: =IF('주간 입력'!C107="",0,'주간 입력'!C107)+IF('주간 입력'!C108="",0,'주간 입력'!C108*0.05)+IF('주간 입력'!C109="",0,'주간 입력'!C109) | Q10: =IF(E10="","",J10+K10+L10+M10+N10+O10+P10) | R10: =IF(E10="","",E10-Q10) | S10: =IF(E10="","",F10-I10-I10*0.1) | T10: ='주간 입력'!C110
A11: ='주간 입력'!C113 | B11: ='주간 입력'!C114 | C11: ='주간 입력'!C115 | D11: ='주간 입력'!C116 | E11: ='주간 입력'!C118 | F11: ='주간 입력'!C119 | G11: =IF(E11="","",E11+F11) | H11: =IF(E11="","",E11*0.15) | I11: =IF(E11="","",IF(F11="",0,F11*0.13)) | J11: =IF(E11="","",H11+I11) | K11: =IF(E11="","",J11*0.1) | L11: =IF('주간 입력'!C114=4,3000000,0) | M11: =IF(L11=0,0,L11*0.1) | N11: =IF('주간 입력'!C114=4,55000+15900+50000,0) | O11: =(IF('주간 입력'!C121="",0,'주간 입력'!C121)+IF('주간 입력'!C122="",0,'주간 입력'!C122)+IF('주간 입력'!C123="",0,'주간 입력'!C123))*0.95 | P11: =IF('주간 입력'!C125="",0,'주간 입력'!C125)+IF('주간 입력'!C126="",0,'주간 입력'!C126*0.05)+IF('주간 입력'!C127="",0,'주간 입력'!C127) | Q11: =IF(E11="","",J11+K11+L11+M11+N11+O11+P11) | R11: =IF(E11="","",E11-Q11) | S11: =IF(E11="","",F11-I11-I11*0.1) | T11: ='주간 입력'!C128
A12: ='주간 입력'!C131 | B12: ='주간 입력'!C132 | C12: ='주간 입력'!C133 | D12: ='주간 입력'!C134 | E12: ='주간 입력'!C136 | F12: ='주간 입력'!C137 | G12: =IF(E12="","",E12+F12) | H12: =IF(E12="","",E12*0.15) | I12: =IF(E12="","",IF(F12="",0,F12*0.13)) | J12: =IF(E12="","",H12+I12) | K12: =IF(E12="","",J12*0.1) | L12: =IF('주간 입력'!C132=4,3000000,0) | M12: =IF(L12=0,0,L12*0.1) | N12: =IF('주간 입력'!C132=4,55000+15900+50000,0) | O12: =(IF('주간 입력'!C139="",0,'주간 입력'!C139)+IF('주간 입력'!C140="",0,'주간 입력'!C140)+IF('주간 입력'!C141="",0,'주간 입력'!C141))*0.95 | P12: =IF('주간 입력'!C143="",0,'주간 입력'!C143)+IF('주간 입력'!C144="",0,'주간 입력'!C144*0.05)+IF('주간 입력'!C145="",0,'주간 입력'!C145) | Q12: =IF(E12="","",J12+K12+L12+M12+N12+O12+P12) | R12: =IF(E12="","",E12-Q12) | S12: =IF(E12="","",F12-I12-I12*0.1) | T12: ='주간 입력'!C146
A13: ='주간 입력'!C149 | B13: ='주간 입력'!C150 | C13: ='주간 입력'!C151 | D13: ='주간 입력'!C152 | E13: ='주간 입력'!C154 | F13: ='주간 입력'!C155 | G13: =IF(E13="","",E13+F13) | H13: =IF(E13="","",E13*0.15) | I13: =IF(E13="","",IF(F13="",0,F13*0.13)) | J13: =IF(E13="","",H13+I13) | K13: =IF(E13="","",J13*0.1) | L13: =IF('주간 입력'!C150=4,3000000,0) | M13: =IF(L13=0,0,L13*0.1) | N13: =IF('주간 입력'!C150=4,55000+15900+50000,0) | O13: =(IF('주간 입력'!C157="",0,'주간 입력'!C157)+IF('주간 입력'!C158="",0,'주간 입력'!C158)+IF('주간 입력'!C159="",0,'주간 입력'!C159))*0.95 | P13: =IF('주간 입력'!C161="",0,'주간 입력'!C161)+IF('주간 입력'!C162="",0,'주간 입력'!C162*0.05)+IF('주간 입력'!C163="",0,'주간 입력'!C163) | Q13: =IF(E13="","",J13+K13+L13+M13+N13+O13+P13) | R13: =IF(E13="","",E13-Q13) | S13: =IF(E13="","",F13-I13-I13*0.1) | T13: ='주간 입력'!C164
A14: ='주간 입력'!C167 | B14: ='주간 입력'!C168 | C14: ='주간 입력'!C169 | D14: ='주간 입력'!C170 | E14: ='주간 입력'!C172 | F14: ='주간 입력'!C173 | G14: =IF(E14="","",E14+F14) | H14: =IF(E14="","",E14*0.15) | I14: =IF(E14="","",IF(F14="",0,F14*0.13)) | J14: =IF(E14="","",H14+I14) | K14: =IF(E14="","",J14*0.1) | L14: =IF('주간 입력'!C168=4,3000000,0) | M14: =IF(L14=0,0,L14*0.1) | N14: =IF('주간 입력'!C168=4,55000+15900+50000,0) | O14: =(IF('주간 입력'!C175="",0,'주간 입력'!C175)+IF('주간 입력'!C176="",0,'주간 입력'!C176)+IF('주간 입력'!C177="",0,'주간 입력'!C177))*0.95 | P14: =IF('주간 입력'!C179="",0,'주간 입력'!C179)+IF('주간 입력'!C180="",0,'주간 입력'!C180*0.05)+IF('주간 입력'!C181="",0,'주간 입력'!C181) | Q14: =IF(E14="","",J14+K14+L14+M14+N14+O14+P14) | R14: =IF(E14="","",E14-Q14) | S14: =IF(E14="","",F14-I14-I14*0.1) | T14: ='주간 입력'!C182
A15: 2월 | B15: 소계 | E15: =SUM(E10:E14) | F15: =SUM(F10:F14) | G15: =SUM(G10:G14) | H15: =SUM(H10:H14) | I15: =SUM(I10:I14) | J15: =SUM(J10:J14) | K15: =SUM(K10:K14) | L15: =SUM(L10:L14) | ... S15: =SUM(S10:S14)
A16: ='주간 입력'!C185 | B16: ='주간 입력'!C186 | C16: ='주간 입력'!C187 | D16: ='주간 입력'!C188 | E16: ='주간 입력'!C190 | F16: ='주간 입력'!C191 | G16: =IF(E16="","",E16+F16) | H16: =IF(E16="","",E16*0.15) | I16: =IF(E16="","",IF(F16="",0,F16*0.13)) | J16: =IF(E16="","",H16+I16) | K16: =IF(E16="","",J16*0.1) | L16: =IF('주간 입력'!C186=4,3000000,0) | M16: =IF(L16=0,0,L16*0.1) | N16: =IF('주간 입력'!C186=4,55000+15900+50000,0) | O16: =(IF('주간 입력'!C193="",0,'주간 입력'!C193)+IF('주간 입력'!C194="",0,'주간 입력'!C194)+IF('주간 입력'!C195="",0,'주간 입력'!C195))*0.95 | P16: =IF('주간 입력'!C197="",0,'주간 입력'!C197)+IF('주간 입력'!C198="",0,'주간 입력'!C198*0.05)+IF('주간 입력'!C199="",0,'주간 입력'!C199) | Q16: =IF(E16="","",J16+K16+L16+M16+N16+O16+P16) | R16: =IF(E16="","",E16-Q16) | S16: =IF(E16="","",F16-I16-I16*0.1) | T16: ='주간 입력'!C200
A17: ='주간 입력'!C203 | B17: ='주간 입력'!C204 | C17: ='주간 입력'!C205 | D17: ='주간 입력'!C206 | E17: ='주간 입력'!C208 | F17: ='주간 입력'!C209 | G17: =IF(E17="","",E17+F17) | H17: =IF(E17="","",E17*0.15) | I17: =IF(E17="","",IF(F17="",0,F17*0.13)) | J17: =IF(E17="","",H17+I17) | K17: =IF(E17="","",J17*0.1) | L17: =IF('주간 입력'!C204=4,3000000,0) | M17: =IF(L17=0,0,L17*0.1) | N17: =IF('주간 입력'!C204=4,55000+15900+50000,0) | O17: =(IF('주간 입력'!C211="",0,'주간 입력'!C211)+IF('주간 입력'!C212="",0,'주간 입력'!C212)+IF('주간 입력'!C213="",0,'주간 입력'!C213))*0.95 | P17: =IF('주간 입력'!C215="",0,'주간 입력'!C215)+IF('주간 입력'!C216="",0,'주간 입력'!C216*0.05)+IF('주간 입력'!C217="",0,'주간 입력'!C217) | Q17: =IF(E17="","",J17+K17+L17+M17+N17+O17+P17) | R17: =IF(E17="","",E17-Q17) | S17: =IF(E17="","",F17-I17-I17*0.1) | T17: ='주간 입력'!C218
A18: ='주간 입력'!C221 | B18: ='주간 입력'!C222 | C18: ='주간 입력'!C223 | D18: ='주간 입력'!C224 | E18: ='주간 입력'!C226 | F18: ='주간 입력'!C227 | G18: =IF(E18="","",E18+F18) | H18: =IF(E18="","",E18*0.15) | I18: =IF(E18="","",IF(F18="",0,F18*0.13)) | J18: =IF(E18="","",H18+I18) | K18: =IF(E18="","",J18*0.1) | L18: =IF('주간 입력'!C222=4,3000000,0) | M18: =IF(L18=0,0,L18*0.1) | N18: =IF('주간 입력'!C222=4,55000+15900+50000,0) | O18: =(IF('주간 입력'!C229="",0,'주간 입력'!C229)+IF('주간 입력'!C230="",0,'주간 입력'!C230)+IF('주간 입력'!C231="",0,'주간 입력'!C231))*0.95 | P18: =IF('주간 입력'!C233="",0,'주간 입력'!C233)+IF('주간 입력'!C234="",0,'주간 입력'!C234*0.05)+IF('주간 입력'!C235="",0,'주간 입력'!C235) | Q18: =IF(E18="","",J18+K18+L18+M18+N18+O18+P18) | R18: =IF(E18="","",E18-Q18) | S18: =IF(E18="","",F18-I18-I18*0.1) | T18: ='주간 입력'!C236
A19: ='주간 입력'!C239 | B19: ='주간 입력'!C240 | C19: ='주간 입력'!C241 | D19: ='주간 입력'!C242 | E19: ='주간 입력'!C244 | F19: ='주간 입력'!C245 | G19: =IF(E19="","",E19+F19) | H19: =IF(E19="","",E19*0.15) | I19: =IF(E19="","",IF(F19="",0,F19*0.13)) | J19: =IF(E19="","",H19+I19) | K19: =IF(E19="","",J19*0.1) | L19: =IF('주간 입력'!C240=4,3000000,0) | M19: =IF(L19=0,0,L19*0.1) | N19: =IF('주간 입력'!C240=4,55000+15900+50000,0) | O19: =(IF('주간 입력'!C247="",0,'주간 입력'!C247)+IF('주간 입력'!C248="",0,'주간 입력'!C248)+IF('주간 입력'!C249="",0,'주간 입력'!C249))*0.95 | P19: =IF('주간 입력'!C251="",0,'주간 입력'!C251)+IF('주간 입력'!C252="",0,'주간 입력'!C252*0.05)+IF('주간 입력'!C253="",0,'주간 입력'!C253) | Q19: =IF(E19="","",J19+K19+L19+M19+N19+O19+P19) | R19: =IF(E19="","",E19-Q19) | S19: =IF(E19="","",F19-I19-I19*0.1) | T19: ='주간 입력'!C254
A20: ='주간 입력'!C257 | B20: ='주간 입력'!C258 | C20: ='주간 입력'!C259 | D20: ='주간 입력'!C260 | E20: ='주간 입력'!C262 | F20: ='주간 입력'!C263 | G20: =IF(E20="","",E20+F20) | H20: =IF(E20="","",E20*0.15) | I20: =IF(E20="","",IF(F20="",0,F20*0.13)) | J20: =IF(E20="","",H20+I20) | K20: =IF(E20="","",J20*0.1) | L20: =IF('주간 입력'!C258=4,3000000,0) | M20: =IF(L20=0,0,L20*0.1) | N20: =IF('주간 입력'!C258=4,55000+15900+50000,0) | O20: =(IF('주간 입력'!C265="",0,'주간 입력'!C265)+IF('주간 입력'!C266="",0,'주간 입력'!C266)+IF('주간 입력'!C267="",0,'주간 입력'!C267))*0.95 | P20: =IF('주간 입력'!C269="",0,'주간 입력'!C269)+IF('주간 입력'!C270="",0,'주간 입력'!C270*0.05)+IF('주간 입력'!C271="",0,'주간 입력'!C271) | Q20: =IF(E20="","",J20+K20+L20+M20+N20+O20+P20) | R20: =IF(E20="","",E20-Q20) | S20: =IF(E20="","",F20-I20-I20*0.1) | T20: ='주간 입력'!C272
A21: 3월 | B21: 소계 | E21: =SUM(E16:E20) | F21: =SUM(F16:F20) | G21: =SUM(G16:G20) | H21: =SUM(H16:H20) | I21: =SUM(I16:I20) | J21: =SUM(J16:J20) | K21: =SUM(K16:K20) | L21: =SUM(L16:L20) | ... S21: =SUM(S16:S20)
A22: ='주간 입력'!C275 | B22: ='주간 입력'!C276 | C22: ='주간 입력'!C277 | D22: ='주간 입력'!C278 | E22: ='주간 입력'!C280 | F22: ='주간 입력'!C281 | G22: =IF(E22="","",E22+F22) | H22: =IF(E22="","",E22*0.15) | I22: =IF(E22="","",IF(F22="",0,F22*0.13)) | J22: =IF(E22="","",H22+I22) | K22: =IF(E22="","",J22*0.1) | L22: =IF('주간 입력'!C276=4,3000000,0) | M22: =IF(L22=0,0,L22*0.1) | N22: =IF('주간 입력'!C276=4,55000+15900+50000,0) | O22: =(IF('주간 입력'!C283="",0,'주간 입력'!C283)+IF('주간 입력'!C284="",0,'주간 입력'!C284)+IF('주간 입력'!C285="",0,'주간 입력'!C285))*0.95 | P22: =IF('주간 입력'!C287="",0,'주간 입력'!C287)+IF('주간 입력'!C288="",0,'주간 입력'!C288*0.05)+IF('주간 입력'!C289="",0,'주간 입력'!C289) | Q22: =IF(E22="","",J22+K22+L22+M22+N22+O22+P22) | R22: =IF(E22="","",E22-Q22) | S22: =IF(E22="","",F22-I22-I22*0.1) | T22: ='주간 입력'!C290
A23: ='주간 입력'!C293 | B23: ='주간 입력'!C294 | C23: ='주간 입력'!C295 | D23: ='주간 입력'!C296 | E23: ='주간 입력'!C298 | F23: ='주간 입력'!C299 | G23: =IF(E23="","",E23+F23) | H23: =IF(E23="","",E23*0.15) | I23: =IF(E23="","",IF(F23="",0,F23*0.13)) | J23: =IF(E23="","",H23+I23) | K23: =IF(E23="","",J23*0.1) | L23: =IF('주간 입력'!C294=4,3000000,0) | M23: =IF(L23=0,0,L23*0.1) | N23: =IF('주간 입력'!C294=4,55000+15900+50000,0) | O23: =(IF('주간 입력'!C301="",0,'주간 입력'!C301)+IF('주간 입력'!C302="",0,'주간 입력'!C302)+IF('주간 입력'!C303="",0,'주간 입력'!C303))*0.95 | P23: =IF('주간 입력'!C305="",0,'주간 입력'!C305)+IF('주간 입력'!C306="",0,'주간 입력'!C306*0.05)+IF('주간 입력'!C307="",0,'주간 입력'!C307) | Q23: =IF(E23="","",J23+K23+L23+M23+N23+O23+P23) | R23: =IF(E23="","",E23-Q23) | S23: =IF(E23="","",F23-I23-I23*0.1) | T23: ='주간 입력'!C308
A24: ='주간 입력'!C311 | B24: ='주간 입력'!C312 | C24: ='주간 입력'!C313 | D24: ='주간 입력'!C314 | E24: ='주간 입력'!C316 | F24: ='주간 입력'!C317 | G24: =IF(E24="","",E24+F24) | H24: =IF(E24="","",E24*0.15) | I24: =IF(E24="","",IF(F24="",0,F24*0.13)) | J24: =IF(E24="","",H24+I24) | K24: =IF(E24="","",J24*0.1) | L24: =IF('주간 입력'!C312=4,3000000,0) | M24: =IF(L24=0,0,L24*0.1) | N24: =IF('주간 입력'!C312=4,55000+15900+50000,0) | O24: =(IF('주간 입력'!C319="",0,'주간 입력'!C319)+IF('주간 입력'!C320="",0,'주간 입력'!C320)+IF('주간 입력'!C321="",0,'주간 입력'!C321))*0.95 | P24: =IF('주간 입력'!C323="",0,'주간 입력'!C323)+IF('주간 입력'!C324="",0,'주간 입력'!C324*0.05)+IF('주간 입력'!C325="",0,'주간 입력'!C325) | Q24: =IF(E24="","",J24+K24+L24+M24+N24+O24+P24) | R24: =IF(E24="","",E24-Q24) | S24: =IF(E24="","",F24-I24-I24*0.1) | T24: ='주간 입력'!C326
A25: ='주간 입력'!C329 | B25: ='주간 입력'!C330 | C25: ='주간 입력'!C331 | D25: ='주간 입력'!C332 | E25: ='주간 입력'!C334 | F25: ='주간 입력'!C335 | G25: =IF(E25="","",E25+F25) | H25: =IF(E25="","",E25*0.15) | I25: =IF(E25="","",IF(F25="",0,F25*0.13)) | J25: =IF(E25="","",H25+I25) | K25: =IF(E25="","",J25*0.1) | L25: =IF('주간 입력'!C330=4,3000000,0) | M25: =IF(L25=0,0,L25*0.1) | N25: =IF('주간 입력'!C330=4,55000+15900+50000,0) | O25: =(IF('주간 입력'!C337="",0,'주간 입력'!C337)+IF('주간 입력'!C338="",0,'주간 입력'!C338)+IF('주간 입력'!C339="",0,'주간 입력'!C339))*0.95 | P25: =IF('주간 입력'!C341="",0,'주간 입력'!C341)+IF('주간 입력'!C342="",0,'주간 입력'!C342*0.05)+IF('주간 입력'!C343="",0,'주간 입력'!C343) | Q25: =IF(E25="","",J25+K25+L25+M25+N25+O25+P25) | R25: =IF(E25="","",E25-Q25) | S25: =IF(E25="","",F25-I25-I25*0.1) | T25: ='주간 입력'!C344
A26: ='주간 입력'!C347 | B26: ='주간 입력'!C348 | C26: ='주간 입력'!C349 | D26: ='주간 입력'!C350 | E26: ='주간 입력'!C352 | F26: ='주간 입력'!C353 | G26: =IF(E26="","",E26+F26) | H26: =IF(E26="","",E26*0.15) | I26: =IF(E26="","",IF(F26="",0,F26*0.13)) | J26: =IF(E26="","",H26+I26) | K26: =IF(E26="","",J26*0.1) | L26: =IF('주간 입력'!C348=4,3000000,0) | M26: =IF(L26=0,0,L26*0.1) | N26: =IF('주간 입력'!C348=4,55000+15900+50000,0) | O26: =(IF('주간 입력'!C355="",0,'주간 입력'!C355)+IF('주간 입력'!C356="",0,'주간 입력'!C356)+IF('주간 입력'!C357="",0,'주간 입력'!C357))*0.95 | P26: =IF('주간 입력'!C359="",0,'주간 입력'!C359)+IF('주간 입력'!C360="",0,'주간 입력'!C360*0.05)+IF('주간 입력'!C361="",0,'주간 입력'!C361) | Q26: =IF(E26="","",J26+K26+L26+M26+N26+O26+P26) | R26: =IF(E26="","",E26-Q26) | S26: =IF(E26="","",F26-I26-I26*0.1) | T26: ='주간 입력'!C362
A27: 4월 | B27: 소계 | E27: =SUM(E22:E26) | F27: =SUM(F22:F26) | G27: =SUM(G22:G26) | H27: =SUM(H22:H26) | I27: =SUM(I22:I26) | J27: =SUM(J22:J26) | K27: =SUM(K22:K26) | L27: =SUM(L22:L26) | ... S27: =SUM(S22:S26)
A28: ='주간 입력'!C365 | B28: ='주간 입력'!C366 | C28: ='주간 입력'!C367 | D28: ='주간 입력'!C368 | E28: ='주간 입력'!C370 | F28: ='주간 입력'!C371 | G28: =IF(E28="","",E28+F28) | H28: =IF(E28="","",E28*0.15) | I28: =IF(E28="","",IF(F28="",0,F28*0.13)) | J28: =IF(E28="","",H28+I28) | K28: =IF(E28="","",J28*0.1) | L28: =IF('주간 입력'!C366=4,3000000,0) | M28: =IF(L28=0,0,L28*0.1) | N28: =IF('주간 입력'!C366=4,55000+15900+50000,0) | O28: =(IF('주간 입력'!C373="",0,'주간 입력'!C373)+IF('주간 입력'!C374="",0,'주간 입력'!C374)+IF('주간 입력'!C375="",0,'주간 입력'!C375))*0.95 | P28: =IF('주간 입력'!C377="",0,'주간 입력'!C377)+IF('주간 입력'!C378="",0,'주간 입력'!C378*0.05)+IF('주간 입력'!C379="",0,'주간 입력'!C379) | Q28: =IF(E28="","",J28+K28+L28+M28+N28+O28+P28) | R28: =IF(E28="","",E28-Q28) | S28: =IF(E28="","",F28-I28-I28*0.1) | T28: ='주간 입력'!C380
A29: ='주간 입력'!C383 | B29: ='주간 입력'!C384 | C29: ='주간 입력'!C385 | D29: ='주간 입력'!C386 | E29: ='주간 입력'!C388 | F29: ='주간 입력'!C389 | G29: =IF(E29="","",E29+F29) | H29: =IF(E29="","",E29*0.15) | I29: =IF(E29="","",IF(F29="",0,F29*0.13)) | J29: =IF(E29="","",H29+I29) | K29: =IF(E29="","",J29*0.1) | L29: =IF('주간 입력'!C384=4,3000000,0) | M29: =IF(L29=0,0,L29*0.1) | N29: =IF('주간 입력'!C384=4,55000+15900+50000,0) | O29: =(IF('주간 입력'!C391="",0,'주간 입력'!C391)+IF('주간 입력'!C392="",0,'주간 입력'!C392)+IF('주간 입력'!C393="",0,'주간 입력'!C393))*0.95 | P29: =IF('주간 입력'!C395="",0,'주간 입력'!C395)+IF('주간 입력'!C396="",0,'주간 입력'!C396*0.05)+IF('주간 입력'!C397="",0,'주간 입력'!C397) | Q29: =IF(E29="","",J29+K29+L29+M29+N29+O29+P29) | R29: =IF(E29="","",E29-Q29) | S29: =IF(E29="","",F29-I29-I29*0.1) | T29: ='주간 입력'!C398
A30: ='주간 입력'!C401 | B30: ='주간 입력'!C402 | C30: ='주간 입력'!C403 | D30: ='주간 입력'!C404 | E30: ='주간 입력'!C406 | F30: ='주간 입력'!C407 | G30: =IF(E30="","",E30+F30) | H30: =IF(E30="","",E30*0.15) | I30: =IF(E30="","",IF(F30="",0,F30*0.13)) | J30: =IF(E30="","",H30+I30) | K30: =IF(E30="","",J30*0.1) | L30: =IF('주간 입력'!C402=4,3000000,0) | M30: =IF(L30=0,0,L30*0.1) | N30: =IF('주간 입력'!C402=4,55000+15900+50000,0) | O30: =(IF('주간 입력'!C409="",0,'주간 입력'!C409)+IF('주간 입력'!C410="",0,'주간 입력'!C410)+IF('주간 입력'!C411="",0,'주간 입력'!C411))*0.95 | P30: =IF('주간 입력'!C413="",0,'주간 입력'!C413)+IF('주간 입력'!C414="",0,'주간 입력'!C414*0.05)+IF('주간 입력'!C415="",0,'주간 입력'!C415) | Q30: =IF(E30="","",J30+K30+L30+M30+N30+O30+P30) | R30: =IF(E30="","",E30-Q30) | S30: =IF(E30="","",F30-I30-I30*0.1) | T30: ='주간 입력'!C416
A31: ='주간 입력'!C419 | B31: ='주간 입력'!C420 | C31: ='주간 입력'!C421 | D31: ='주간 입력'!C422 | E31: ='주간 입력'!C424 | F31: ='주간 입력'!C425 | G31: =IF(E31="","",E31+F31) | H31: =IF(E31="","",E31*0.15) | I31: =IF(E31="","",IF(F31="",0,F31*0.13)) | J31: =IF(E31="","",H31+I31) | K31: =IF(E31="","",J31*0.1) | L31: =IF('주간 입력'!C420=4,3000000,0) | M31: =IF(L31=0,0,L31*0.1) | N31: =IF('주간 입력'!C420=4,55000+15900+50000,0) | O31: =(IF('주간 입력'!C427="",0,'주간 입력'!C427)+IF('주간 입력'!C428="",0,'주간 입력'!C428)+IF('주간 입력'!C429="",0,'주간 입력'!C429))*0.95 | P31: =IF('주간 입력'!C431="",0,'주간 입력'!C431)+IF('주간 입력'!C432="",0,'주간 입력'!C432*0.05)+IF('주간 입력'!C433="",0,'주간 입력'!C433) | Q31: =IF(E31="","",J31+K31+L31+M31+N31+O31+P31) | R31: =IF(E31="","",E31-Q31) | S31: =IF(E31="","",F31-I31-I31*0.1) | T31: ='주간 입력'!C434
A32: ='주간 입력'!C437 | B32: ='주간 입력'!C438 | C32: ='주간 입력'!C439 | D32: ='주간 입력'!C440 | E32: ='주간 입력'!C442 | F32: ='주간 입력'!C443 | G32: =IF(E32="","",E32+F32) | H32: =IF(E32="","",E32*0.15) | I32: =IF(E32="","",IF(F32="",0,F32*0.13)) | J32: =IF(E32="","",H32+I32) | K32: =IF(E32="","",J32*0.1) | L32: =IF('주간 입력'!C438=4,3000000,0) | M32: =IF(L32=0,0,L32*0.1) | N32: =IF('주간 입력'!C438=4,55000+15900+50000,0) | O32: =(IF('주간 입력'!C445="",0,'주간 입력'!C445)+IF('주간 입력'!C446="",0,'주간 입력'!C446)+IF('주간 입력'!C447="",0,'주간 입력'!C447))*0.95 | P32: =IF('주간 입력'!C449="",0,'주간 입력'!C449)+IF('주간 입력'!C450="",0,'주간 입력'!C450*0.05)+IF('주간 입력'!C451="",0,'주간 입력'!C451) | Q32: =IF(E32="","",J32+K32+L32+M32+N32+O32+P32) | R32: =IF(E32="","",E32-Q32) | S32: =IF(E32="","",F32-I32-I32*0.1) | T32: ='주간 입력'!C452
A33: 5월 | B33: 소계 | E33: =SUM(E28:E32) | F33: =SUM(F28:F32) | G33: =SUM(G28:G32) | H33: =SUM(H28:H32) | I33: =SUM(I28:I32) | J33: =SUM(J28:J32) | K33: =SUM(K28:K32) | L33: =SUM(L28:L32) | ... S33: =SUM(S28:S32)
A34: ='주간 입력'!C455 | B34: ='주간 입력'!C456 | C34: ='주간 입력'!C457 | D34: ='주간 입력'!C458 | E34: ='주간 입력'!C460 | F34: ='주간 입력'!C461 | G34: =IF(E34="","",E34+F34) | H34: =IF(E34="","",E34*0.15) | I34: =IF(E34="","",IF(F34="",0,F34*0.13)) | J34: =IF(E34="","",H34+I34) | K34: =IF(E34="","",J34*0.1) | L34: =IF('주간 입력'!C456=4,3000000,0) | M34: =IF(L34=0,0,L34*0.1) | N34: =IF('주간 입력'!C456=4,55000+15900+50000,0) | O34: =(IF('주간 입력'!C463="",0,'주간 입력'!C463)+IF('주간 입력'!C464="",0,'주간 입력'!C464)+IF('주간 입력'!C465="",0,'주간 입력'!C465))*0.95 | P34: =IF('주간 입력'!C467="",0,'주간 입력'!C467)+IF('주간 입력'!C468="",0,'주간 입력'!C468*0.05)+IF('주간 입력'!C469="",0,'주간 입력'!C469) | Q34: =IF(E34="","",J34+K34+L34+M34+N34+O34+P34) | R34: =IF(E34="","",E34-Q34) | S34: =IF(E34="","",F34-I34-I34*0.1) | T34: ='주간 입력'!C470
A35: ='주간 입력'!C473 | B35: ='주간 입력'!C474 | C35: ='주간 입력'!C475 | D35: ='주간 입력'!C476 | E35: ='주간 입력'!C478 | F35: ='주간 입력'!C479 | G35: =IF(E35="","",E35+F35) | H35: =IF(E35="","",E35*0.15) | I35: =IF(E35="","",IF(F35="",0,F35*0.13)) | J35: =IF(E35="","",H35+I35) | K35: =IF(E35="","",J35*0.1) | L35: =IF('주간 입력'!C474=4,3000000,0) | M35: =IF(L35=0,0,L35*0.1) | N35: =IF('주간 입력'!C474=4,55000+15900+50000,0) | O35: =(IF('주간 입력'!C481="",0,'주간 입력'!C481)+IF('주간 입력'!C482="",0,'주간 입력'!C482)+IF('주간 입력'!C483="",0,'주간 입력'!C483))*0.95 | P35: =IF('주간 입력'!C485="",0,'주간 입력'!C485)+IF('주간 입력'!C486="",0,'주간 입력'!C486*0.05)+IF('주간 입력'!C487="",0,'주간 입력'!C487) | Q35: =IF(E35="","",J35+K35+L35+M35+N35+O35+P35) | R35: =IF(E35="","",E35-Q35) | S35: =IF(E35="","",F35-I35-I35*0.1) | T35: ='주간 입력'!C488
A36: ='주간 입력'!C491 | B36: ='주간 입력'!C492 | C36: ='주간 입력'!C493 | D36: ='주간 입력'!C494 | E36: ='주간 입력'!C496 | F36: ='주간 입력'!C497 | G36: =IF(E36="","",E36+F36) | H36: =IF(E36="","",E36*0.15) | I36: =IF(E36="","",IF(F36="",0,F36*0.13)) | J36: =IF(E36="","",H36+I36) | K36: =IF(E36="","",J36*0.1) | L36: =IF('주간 입력'!C492=4,3000000,0) | M36: =IF(L36=0,0,L36*0.1) | N36: =IF('주간 입력'!C492=4,55000+15900+50000,0) | O36: =(IF('주간 입력'!C499="",0,'주간 입력'!C499)+IF('주간 입력'!C500="",0,'주간 입력'!C500)+IF('주간 입력'!C501="",0,'주간 입력'!C501))*0.95 | P36: =IF('주간 입력'!C503="",0,'주간 입력'!C503)+IF('주간 입력'!C504="",0,'주간 입력'!C504*0.05)+IF('주간 입력'!C505="",0,'주간 입력'!C505) | Q36: =IF(E36="","",J36+K36+L36+M36+N36+O36+P36) | R36: =IF(E36="","",E36-Q36) | S36: =IF(E36="","",F36-I36-I36*0.1) | T36: ='주간 입력'!C506
A37: ='주간 입력'!C509 | B37: ='주간 입력'!C510 | C37: ='주간 입력'!C511 | D37: ='주간 입력'!C512 | E37: ='주간 입력'!C514 | F37: ='주간 입력'!C515 | G37: =IF(E37="","",E37+F37) | H37: =IF(E37="","",E37*0.15) | I37: =IF(E37="","",IF(F37="",0,F37*0.13)) | J37: =IF(E37="","",H37+I37) | K37: =IF(E37="","",J37*0.1) | L37: =IF('주간 입력'!C510=4,3000000,0) | M37: =IF(L37=0,0,L37*0.1) | N37: =IF('주간 입력'!C510=4,55000+15900+50000,0) | O37: =(IF('주간 입력'!C517="",0,'주간 입력'!C517)+IF('주간 입력'!C518="",0,'주간 입력'!C518)+IF('주간 입력'!C519="",0,'주간 입력'!C519))*0.95 | P37: =IF('주간 입력'!C521="",0,'주간 입력'!C521)+IF('주간 입력'!C522="",0,'주간 입력'!C522*0.05)+IF('주간 입력'!C523="",0,'주간 입력'!C523) | Q37: =IF(E37="","",J37+K37+L37+M37+N37+O37+P37) | R37: =IF(E37="","",E37-Q37) | S37: =IF(E37="","",F37-I37-I37*0.1) | T37: ='주간 입력'!C524
A38: ='주간 입력'!C527 | B38: ='주간 입력'!C528 | C38: ='주간 입력'!C529 | D38: ='주간 입력'!C530 | E38: ='주간 입력'!C532 | F38: ='주간 입력'!C533 | G38: =IF(E38="","",E38+F38) | H38: =IF(E38="","",E38*0.15) | I38: =IF(E38="","",IF(F38="",0,F38*0.13)) | J38: =IF(E38="","",H38+I38) | K38: =IF(E38="","",J38*0.1) | L38: =IF('주간 입력'!C528=4,3000000,0) | M38: =IF(L38=0,0,L38*0.1) | N38: =IF('주간 입력'!C528=4,55000+15900+50000,0) | O38: =(IF('주간 입력'!C535="",0,'주간 입력'!C535)+IF('주간 입력'!C536="",0,'주간 입력'!C536)+IF('주간 입력'!C537="",0,'주간 입력'!C537))*0.95 | P38: =IF('주간 입력'!C539="",0,'주간 입력'!C539)+IF('주간 입력'!C540="",0,'주간 입력'!C540*0.05)+IF('주간 입력'!C541="",0,'주간 입력'!C541) | Q38: =IF(E38="","",J38+K38+L38+M38+N38+O38+P38) | R38: =IF(E38="","",E38-Q38) | S38: =IF(E38="","",F38-I38-I38*0.1) | T38: ='주간 입력'!C542
A39: 6월 | B39: 소계 | E39: =SUM(E34:E38) | F39: =SUM(F34:F38) | G39: =SUM(G34:G38) | H39: =SUM(H34:H38) | I39: =SUM(I34:I38) | J39: =SUM(J34:J38) | K39: =SUM(K34:K38) | L39: =SUM(L34:L38) | ... S39: =SUM(S34:S38)
A40: ='주간 입력'!C545 | B40: ='주간 입력'!C546 | C40: ='주간 입력'!C547 | D40: ='주간 입력'!C548 | E40: ='주간 입력'!C550 | F40: ='주간 입력'!C551 | G40: =IF(E40="","",E40+F40) | H40: =IF(E40="","",E40*0.15) | I40: =IF(E40="","",IF(F40="",0,F40*0.13)) | J40: =IF(E40="","",H40+I40) | K40: =IF(E40="","",J40*0.1) | L40: =IF('주간 입력'!C546=4,3000000,0) | M40: =IF(L40=0,0,L40*0.1) | N40: =IF('주간 입력'!C546=4,55000+15900+50000,0) | O40: =(IF('주간 입력'!C553="",0,'주간 입력'!C553)+IF('주간 입력'!C554="",0,'주간 입력'!C554)+IF('주간 입력'!C555="",0,'주간 입력'!C555))*0.95 | P40: =IF('주간 입력'!C557="",0,'주간 입력'!C557)+IF('주간 입력'!C558="",0,'주간 입력'!C558*0.05)+IF('주간 입력'!C559="",0,'주간 입력'!C559) | Q40: =IF(E40="","",J40+K40+L40+M40+N40+O40+P40) | R40: =IF(E40="","",E40-Q40) | S40: =IF(E40="","",F40-I40-I40*0.1) | T40: ='주간 입력'!C560
...

Sheet 미수금 관리
A1: 미식가의 주방 — 미수금 관리
A2: 기존 미수금 현황 + 상환 계획 (세금계산서 vs 은행거래 비교 기준)
A3: # | B3: 항목 | C3: 원금 | D3: 차감 누적 | E3: 잔액 | F3: 이자 | G3: 상태 | H3: 비고
A4: 1 | B4: 공과금 미수 | C4: 26480630 | E4: =C4-IF(D4="",0,D4) | G4: 미수 | H4: 2024.4~2025.12 누적
A5: 2 | B5: 임대료 미수 | C5: 6600000 | E5: =C5-IF(D5="",0,D5) | G5: 미수
A6: 3 | B6: 현금매출 수수료 미수 | C6: 2303154 | E6: =C6-IF(D6="",0,D6) | G6: 미수
A7: 4 | B7: 관리비 미수 | C7: 2123763 | E7: =C7-IF(D7="",0,D7) | G7: 미수
A8: 5 | B8: 정수기 임대료 미수 | C8: 333900 | E8: =C8-IF(D8="",0,D8) | G8: 미수
A9: 6 | B9: 이자 (연 10%) | C9: 2766151 | E9: =C9-IF(D9="",0,D9) | G9: 미수 | H9: 지연이자율 연 10%
B10: 합계 | C10: =SUM(C4:C9) | D10: =SUM(D4:D9) | E10: =SUM(E4:E9) | F10: =SUM(F4:F9)
A12: 📋 미수금 차감 계획 (주간 정산에서 분할 차감)
A13: # | B13: 회차 | C13: 예정일 | D13: 차감금액 | E13: 차감 후 잔액 | H13: 비고
A14: 1 | B14: 1회차 | C14: 2026-03-02 | D14: 6000000 | E14: =E10-D14
A15: 2 | B15: 2회차 | C15: 2026-03-09 | D15: 6000000 | E15: =E14-D15
A16: 3 | B16: 3회차 | C16: 2026-03-16 | D16: 6000000 | E16: =E15-D16
A17: 4 | B17: 4회차 | C17: 2026-03-23 | D17: 6000000 | E17: =E16-D17
A18: 5 | B18: 5회차 | C18: 2026-03-30 | D18: 6000000 | E18: =E17-D18
A19: 6 | B19: 6회차 | C19: 2026-04-06 | D19: 6000000 | E19: =E18-D19
A20: 7 | B20: 7회차 | C20: 2026-04-20 | D20: 4607598 | E20: =E19-D20
