Workbook

Sheet 주간 입력
B1: 📋 미식가의 주방 — 주간 정산 입력
B2: 🟡 노란 칸에 입력 → 하단 [전송] 버튼 클릭
B4: 📅 기본 정보
B5: 월 | D5: ← 1~12
B6: 주차 | D6: ← 1~5
B7: 시작일 | D7: ← 예: 3/3
B8: 종료일 | D8: ← 예: 3/9
B10: 💰 매출
B11: 카드매출 | D11: 원 (POS 카드 매출액)
B12: 현금매출 | D12: 원 (POS 현금 매출액)
B14: ⚡ 공과금 (3주차에 지난달분 입력)
B15: 전기요금 | D15: 원 (고지서 금액 그대로)
B16: 가스요금 | D16: 원 (고지서 금액 그대로)
B17: 수도요금 | D17: 원 (고지서 금액 그대로)
B18: → 95% 자동계산 | C18: =IF(AND(C15="",C16="",C17=""),"",(IF(C15="",0,C15)+IF(C16="",0,C16)+IF(C17="",0,C17))*0.95) | D18: ← 미식가 부담분
B20: 📝 기타 (발생할 때만)
B21: 정화조 | D21: 연 2회 발생 시
B22: 회식매출 | D22: 재생전골 연계 등
B23: 기타비용 | D23: 그 외 비용
B24: 비고 | D24: 특이사항 메모
B26: ▶ 전송 (구글시트에서 버튼으로 전환)
B27: ↑ 구글시트 업로드 후 Apps Script로 버튼 연결하세요
B29: 📌 최근 전송 기록 (최근 5건)
B30: 월/주 | C30: 카드매출 | D30: 현금매출
B31: =IF(데이터!A2="","",데이터!A2&"월 "&데이터!B2&"주") | C31: =IF(데이터!A2="","",데이터!E2) | D31: =IF(데이터!A2="","",데이터!F2)
B32: =IF(데이터!A3="","",데이터!A3&"월 "&데이터!B3&"주") | C32: =IF(데이터!A3="","",데이터!E3) | D32: =IF(데이터!A3="","",데이터!F3)
B33: =IF(데이터!A4="","",데이터!A4&"월 "&데이터!B4&"주") | C33: =IF(데이터!A4="","",데이터!E4) | D33: =IF(데이터!A4="","",데이터!F4)
B34: =IF(데이터!A5="","",데이터!A5&"월 "&데이터!B5&"주") | C34: =IF(데이터!A5="","",데이터!E5) | D34: =IF(데이터!A5="","",데이터!F5)
B35: =IF(데이터!A6="","",데이터!A6&"월 "&데이터!B6&"주") | C35: =IF(데이터!A6="","",데이터!E6) | D35: =IF(데이터!A6="","",데이터!F6)

Sheet 정산 요약
A1: 미식가의 주방 — 주간 정산 요약 (2026년)
A2: ⬜ 전체 자동 — 입력 데이터에서 자동 계산 | 3주차=공과금 / 4주차=임대료+관리비
A3: 월 | B3: 주 | C3: 시작일 | D3: 종료일 | E3: 카드매출 | F3: 현금매출 | G3: 총매출 | H3: 카드수수료 (15%) | I3: 현금수수료 (13%) | J3: 수수료합계 | K3: 수수료 VAT | L3: 임대료 | M3: 임대료 VAT | N3: 관리비+ 고정비 | O3: 공과금 (95%) | P3: 기타비용 | Q3: 총 차감액 | R3: 미식가 카드지급 | S3: 현금 수령액 | T3: 비고
A4: 1 | B4: 1 | C4: =IFERROR(SUMPRODUCT((데이터!$A$2:$A$200=1)*(데이터!$B$2:$B$200=1)*데이터!$C$2:$C$200),"") | D4: =IFERROR(SUMPRODUCT((데이터!$A$2:$A$200=1)*(데이터!$B$2:$B$200=1)*데이터!$D$2:$D$200),"") | E4: =SUMPRODUCT((데이터!$A$2:$A$200=1)*(데이터!$B$2:$B$200=1)*데이터!$E$2:$E$200) | F4: =SUMPRODUCT((데이터!$A$2:$A$200=1)*(데이터!$B$2:$B$200=1)*데이터!$F$2:$F$200) | G4: =IF(E4=0,"",E4+F4) | H4: =IF(E4=0,"",E4*0.15) | I4: =IF(E4=0,"",F4*0.13) | J4: =IF(E4=0,"",H4+I4) | K4: =IF(E4=0,"",J4*0.1) | L4: =IF(AND(E4<>0,B4=4),3000000,0) | M4: =IF(L4=0,0,L4*0.1) | N4: =IF(AND(E4<>0,B4=4),120900,0) | O4: =(SUMPRODUCT((데이터!$A$2:$A$200=1)*(데이터!$B$2:$B$200=1)*데이터!$G$2:$G$200)+SUMPRODUCT((데이터!$A$2:$A$200=1)*(데이터!$B$2:$B$200=1)*데이터!$H$2:$H$200)+SUMPRODUCT((데이터!$A$2:$A$200=1)*(데이터!$B$2:$B$200=1)*데이터!$I$2:$I$200))*0.95 | P4: =SUMPRODUCT((데이터!$A$2:$A$200=1)*(데이터!$B$2:$B$200=1)*데이터!$J$2:$J$200)+SUMPRODUCT((데이터!$A$2:$A$200=1)*(데이터!$B$2:$B$200=1)*데이터!$K$2:$K$200)*0.05+SUMPRODUCT((데이터!$A$2:$A$200=1)*(데이터!$B$2:$B$200=1)*데이터!$L$2:$L$200) | Q4: =IF(E4=0,"",J4+K4+L4+M4+N4+O4+P4) | R4: =IF(E4=0,"",E4-Q4) | S4: =IF(E4=0,"",F4-I4-I4*0.1) | T4: =IFERROR(INDEX(데이터!$M$2:$M$200,MATCH(1,(데이터!$A$2:$A$200=1)*(데이터!$B$2:$B$200=1),0)),"")
A5: 1 | B5: 2 | C5: =IFERROR(SUMPRODUCT((데이터!$A$2:$A$200=1)*(데이터!$B$2:$B$200=2)*데이터!$C$2:$C$200),"") | D5: =IFERROR(SUMPRODUCT((데이터!$A$2:$A$200=1)*(데이터!$B$2:$B$200=2)*데이터!$D$2:$D$200),"") | E5: =SUMPRODUCT((데이터!$A$2:$A$200=1)*(데이터!$B$2:$B$200=2)*데이터!$E$2:$E$200) | F5: =SUMPRODUCT((데이터!$A$2:$A$200=1)*(데이터!$B$2:$B$200=2)*데이터!$F$2:$F$200) | G5: =IF(E5=0,"",E5+F5) | H5: =IF(E5=0,"",E5*0.15) | I5: =IF(E5=0,"",F5*0.13) | J5: =IF(E5=0,"",H5+I5) | K5: =IF(E5=0,"",J5*0.1) | L5: =IF(AND(E5<>0,B5=4),3000000,0) | M5: =IF(L5=0,0,L5*0.1) | N5: =IF(AND(E5<>0,B5=4),120900,0) | O5: =(SUMPRODUCT((데이터!$A$2:$A$200=1)*(데이터!$B$2:$B$200=2)*데이터!$G$2:$G$200)+SUMPRODUCT((데이터!$A$2:$A$200=1)*(데이터!$B$2:$B$200=2)*데이터!$H$2:$H$200)+SUMPRODUCT((데이터!$A$2:$A$200=1)*(데이터!$B$2:$B$200=2)*데이터!$I$2:$I$200))*0.95 | P5: =SUMPRODUCT((데이터!$A$2:$A$200=1)*(데이터!$B$2:$B$200=2)*데이터!$J$2:$J$200)+SUMPRODUCT((데이터!$A$2:$A$200=1)*(데이터!$B$2:$B$200=2)*데이터!$K$2:$K$200)*0.05+SUMPRODUCT((데이터!$A$2:$A$200=1)*(데이터!$B$2:$B$200=2)*데이터!$L$2:$L$200) | Q5: =IF(E5=0,"",J5+K5+L5+M5+N5+O5+P5) | R5: =IF(E5=0,"",E5-Q5) | S5: =IF(E5=0,"",F5-I5-I5*0.1) | T5: =IFERROR(INDEX(데이터!$M$2:$M$200,MATCH(1,(데이터!$A$2:$A$200=1)*(데이터!$B$2:$B$200=2),0)),"")
A6: 1 | B6: 3 | C6: =IFERROR(SUMPRODUCT((데이터!$A$2:$A$200=1)*(데이터!$B$2:$B$200=3)*데이터!$C$2:$C$200),"") | D6: =IFERROR(SUMPRODUCT((데이터!$A$2:$A$200=1)*(데이터!$B$2:$B$200=3)*데이터!$D$2:$D$200),"") | E6: =SUMPRODUCT((데이터!$A$2:$A$200=1)*(데이터!$B$2:$B$200=3)*데이터!$E$2:$E$200) | F6: =SUMPRODUCT((데이터!$A$2:$A$200=1)*(데이터!$B$2:$B$200=3)*데이터!$F$2:$F$200) | G6: =IF(E6=0,"",E6+F6) | H6: =IF(E6=0,"",E6*0.15) | I6: =IF(E6=0,"",F6*0.13) | J6: =IF(E6=0,"",H6+I6) | K6: =IF(E6=0,"",J6*0.1) | L6: =IF(AND(E6<>0,B6=4),3000000,0) | M6: =IF(L6=0,0,L6*0.1) | N6: =IF(AND(E6<>0,B6=4),120900,0) | O6: =(SUMPRODUCT((데이터!$A$2:$A$200=1)*(데이터!$B$2:$B$200=3)*데이터!$G$2:$G$200)+SUMPRODUCT((데이터!$A$2:$A$200=1)*(데이터!$B$2:$B$200=3)*데이터!$H$2:$H$200)+SUMPRODUCT((데이터!$A$2:$A$200=1)*(데이터!$B$2:$B$200=3)*데이터!$I$2:$I$200))*0.95 | P6: =SUMPRODUCT((데이터!$A$2:$A$200=1)*(데이터!$B$2:$B$200=3)*데이터!$J$2:$J$200)+SUMPRODUCT((데이터!$A$2:$A$200=1)*(데이터!$B$2:$B$200=3)*데이터!$K$2:$K$200)*0.05+SUMPRODUCT((데이터!$A$2:$A$200=1)*(데이터!$B$2:$B$200=3)*데이터!$L$2:$L$200) | Q6: =IF(E6=0,"",J6+K6+L6+M6+N6+O6+P6) | R6: =IF(E6=0,"",E6-Q6) | S6: =IF(E6=0,"",F6-I6-I6*0.1) | T6: =IFERROR(INDEX(데이터!$M$2:$M$200,MATCH(1,(데이터!$A$2:$A$200=1)*(데이터!$B$2:$B$200=3),0)),"")
A7: 1 | B7: 4 | C7: =IFERROR(SUMPRODUCT((데이터!$A$2:$A$200=1)*(데이터!$B$2:$B$200=4)*데이터!$C$2:$C$200),"") | D7: =IFERROR(SUMPRODUCT((데이터!$A$2:$A$200=1)*(데이터!$B$2:$B$200=4)*데이터!$D$2:$D$200),"") | E7: =SUMPRODUCT((데이터!$A$2:$A$200=1)*(데이터!$B$2:$B$200=4)*데이터!$E$2:$E$200) | F7: =SUMPRODUCT((데이터!$A$2:$A$200=1)*(데이터!$B$2:$B$200=4)*데이터!$F$2:$F$200) | G7: =IF(E7=0,"",E7+F7) | H7: =IF(E7=0,"",E7*0.15) | I7: =IF(E7=0,"",F7*0.13) | J7: =IF(E7=0,"",H7+I7) | K7: =IF(E7=0,"",J7*0.1) | L7: =IF(AND(E7<>0,B7=4),3000000,0) | M7: =IF(L7=0,0,L7*0.1) | N7: =IF(AND(E7<>0,B7=4),120900,0) | O7: =(SUMPRODUCT((데이터!$A$2:$A$200=1)*(데이터!$B$2:$B$200=4)*데이터!$G$2:$G$200)+SUMPRODUCT((데이터!$A$2:$A$200=1)*(데이터!$B$2:$B$200=4)*데이터!$H$2:$H$200)+SUMPRODUCT((데이터!$A$2:$A$200=1)*(데이터!$B$2:$B$200=4)*데이터!$I$2:$I$200))*0.95 | P7: =SUMPRODUCT((데이터!$A$2:$A$200=1)*(데이터!$B$2:$B$200=4)*데이터!$J$2:$J$200)+SUMPRODUCT((데이터!$A$2:$A$200=1)*(데이터!$B$2:$B$200=4)*데이터!$K$2:$K$200)*0.05+SUMPRODUCT((데이터!$A$2:$A$200=1)*(데이터!$B$2:$B$200=4)*데이터!$L$2:$L$200) | Q7: =IF(E7=0,"",J7+K7+L7+M7+N7+O7+P7) | R7: =IF(E7=0,"",E7-Q7) | S7: =IF(E7=0,"",F7-I7-I7*0.1) | T7: =IFERROR(INDEX(데이터!$M$2:$M$200,MATCH(1,(데이터!$A$2:$A$200=1)*(데이터!$B$2:$B$200=4),0)),"")
A8: 1 | B8: 5 | C8: =IFERROR(SUMPRODUCT((데이터!$A$2:$A$200=1)*(데이터!$B$2:$B$200=5)*데이터!$C$2:$C$200),"") | D8: =IFERROR(SUMPRODUCT((데이터!$A$2:$A$200=1)*(데이터!$B$2:$B$200=5)*데이터!$D$2:$D$200),"") | E8: =SUMPRODUCT((데이터!$A$2:$A$200=1)*(데이터!$B$2:$B$200=5)*데이터!$E$2:$E$200) | F8: =SUMPRODUCT((데이터!$A$2:$A$200=1)*(데이터!$B$2:$B$200=5)*데이터!$F$2:$F$200) | G8: =IF(E8=0,"",E8+F8) | H8: =IF(E8=0,"",E8*0.15) | I8: =IF(E8=0,"",F8*0.13) | J8: =IF(E8=0,"",H8+I8) | K8: =IF(E8=0,"",J8*0.1) | L8: =IF(AND(E8<>0,B8=4),3000000,0) | M8: =IF(L8=0,0,L8*0.1) | N8: =IF(AND(E8<>0,B8=4),120900,0) | O8: =(SUMPRODUCT((데이터!$A$2:$A$200=1)*(데이터!$B$2:$B$200=5)*데이터!$G$2:$G$200)+SUMPRODUCT((데이터!$A$2:$A$200=1)*(데이터!$B$2:$B$200=5)*데이터!$H$2:$H$200)+SUMPRODUCT((데이터!$A$2:$A$200=1)*(데이터!$B$2:$B$200=5)*데이터!$I$2:$I$200))*0.95 | P8: =SUMPRODUCT((데이터!$A$2:$A$200=1)*(데이터!$B$2:$B$200=5)*데이터!$J$2:$J$200)+SUMPRODUCT((데이터!$A$2:$A$200=1)*(데이터!$B$2:$B$200=5)*데이터!$K$2:$K$200)*0.05+SUMPRODUCT((데이터!$A$2:$A$200=1)*(데이터!$B$2:$B$200=5)*데이터!$L$2:$L$200) | Q8: =IF(E8=0,"",J8+K8+L8+M8+N8+O8+P8) | R8: =IF(E8=0,"",E8-Q8) | S8: =IF(E8=0,"",F8-I8-I8*0.1) | T8: =IFERROR(INDEX(데이터!$M$2:$M$200,MATCH(1,(데이터!$A$2:$A$200=1)*(데이터!$B$2:$B$200=5),0)),"")
A9: 1월 | B9: 소계 | E9: =SUM(E4:E8) | F9: =SUM(F4:F8) | G9: =SUM(G4:G8) | H9: =SUM(H4:H8) | I9: =SUM(I4:I8) | J9: =SUM(J4:J8) | K9: =SUM(K4:K8) | L9: =SUM(L4:L8) | ... S9: =SUM(S4:S8)
A10: 2 | B10: 1 | C10: =IFERROR(SUMPRODUCT((데이터!$A$2:$A$200=2)*(데이터!$B$2:$B$200=1)*데이터!$C$2:$C$200),"") | D10: =IFERROR(SUMPRODUCT((데이터!$A$2:$A$200=2)*(데이터!$B$2:$B$200=1)*데이터!$D$2:$D$200),"") | E10: =SUMPRODUCT((데이터!$A$2:$A$200=2)*(데이터!$B$2:$B$200=1)*데이터!$E$2:$E$200) | F10: =SUMPRODUCT((데이터!$A$2:$A$200=2)*(데이터!$B$2:$B$200=1)*데이터!$F$2:$F$200) | G10: =IF(E10=0,"",E10+F10) | H10: =IF(E10=0,"",E10*0.15) | I10: =IF(E10=0,"",F10*0.13) | J10: =IF(E10=0,"",H10+I10) | K10: =IF(E10=0,"",J10*0.1) | L10: =IF(AND(E10<>0,B10=4),3000000,0) | M10: =IF(L10=0,0,L10*0.1) | N10: =IF(AND(E10<>0,B10=4),120900,0) | O10: =(SUMPRODUCT((데이터!$A$2:$A$200=2)*(데이터!$B$2:$B$200=1)*데이터!$G$2:$G$200)+SUMPRODUCT((데이터!$A$2:$A$200=2)*(데이터!$B$2:$B$200=1)*데이터!$H$2:$H$200)+SUMPRODUCT((데이터!$A$2:$A$200=2)*(데이터!$B$2:$B$200=1)*데이터!$I$2:$I$200))*0.95 | P10: =SUMPRODUCT((데이터!$A$2:$A$200=2)*(데이터!$B$2:$B$200=1)*데이터!$J$2:$J$200)+SUMPRODUCT((데이터!$A$2:$A$200=2)*(데이터!$B$2:$B$200=1)*데이터!$K$2:$K$200)*0.05+SUMPRODUCT((데이터!$A$2:$A$200=2)*(데이터!$B$2:$B$200=1)*데이터!$L$2:$L$200) | Q10: =IF(E10=0,"",J10+K10+L10+M10+N10+O10+P10) | R10: =IF(E10=0,"",E10-Q10) | S10: =IF(E10=0,"",F10-I10-I10*0.1) | T10: =IFERROR(INDEX(데이터!$M$2:$M$200,MATCH(1,(데이터!$A$2:$A$200=2)*(데이터!$B$2:$B$200=1),0)),"")
A11: 2 | B11: 2 | C11: =IFERROR(SUMPRODUCT((데이터!$A$2:$A$200=2)*(데이터!$B$2:$B$200=2)*데이터!$C$2:$C$200),"") | D11: =IFERROR(SUMPRODUCT((데이터!$A$2:$A$200=2)*(데이터!$B$2:$B$200=2)*데이터!$D$2:$D$200),"") | E11: =SUMPRODUCT((데이터!$A$2:$A$200=2)*(데이터!$B$2:$B$200=2)*데이터!$E$2:$E$200) | F11: =SUMPRODUCT((데이터!$A$2:$A$200=2)*(데이터!$B$2:$B$200=2)*데이터!$F$2:$F$200) | G11: =IF(E11=0,"",E11+F11) | H11: =IF(E11=0,"",E11*0.15) | I11: =IF(E11=0,"",F11*0.13) | J11: =IF(E11=0,"",H11+I11) | K11: =IF(E11=0,"",J11*0.1) | L11: =IF(AND(E11<>0,B11=4),3000000,0) | M11: =IF(L11=0,0,L11*0.1) | N11: =IF(AND(E11<>0,B11=4),120900,0) | O11: =(SUMPRODUCT((데이터!$A$2:$A$200=2)*(데이터!$B$2:$B$200=2)*데이터!$G$2:$G$200)+SUMPRODUCT((데이터!$A$2:$A$200=2)*(데이터!$B$2:$B$200=2)*데이터!$H$2:$H$200)+SUMPRODUCT((데이터!$A$2:$A$200=2)*(데이터!$B$2:$B$200=2)*데이터!$I$2:$I$200))*0.95 | P11: =SUMPRODUCT((데이터!$A$2:$A$200=2)*(데이터!$B$2:$B$200=2)*데이터!$J$2:$J$200)+SUMPRODUCT((데이터!$A$2:$A$200=2)*(데이터!$B$2:$B$200=2)*데이터!$K$2:$K$200)*0.05+SUMPRODUCT((데이터!$A$2:$A$200=2)*(데이터!$B$2:$B$200=2)*데이터!$L$2:$L$200) | Q11: =IF(E11=0,"",J11+K11+L11+M11+N11+O11+P11) | R11: =IF(E11=0,"",E11-Q11) | S11: =IF(E11=0,"",F11-I11-I11*0.1) | T11: =IFERROR(INDEX(데이터!$M$2:$M$200,MATCH(1,(데이터!$A$2:$A$200=2)*(데이터!$B$2:$B$200=2),0)),"")
A12: 2 | B12: 3 | C12: =IFERROR(SUMPRODUCT((데이터!$A$2:$A$200=2)*(데이터!$B$2:$B$200=3)*데이터!$C$2:$C$200),"") | D12: =IFERROR(SUMPRODUCT((데이터!$A$2:$A$200=2)*(데이터!$B$2:$B$200=3)*데이터!$D$2:$D$200),"") | E12: =SUMPRODUCT((데이터!$A$2:$A$200=2)*(데이터!$B$2:$B$200=3)*데이터!$E$2:$E$200) | F12: =SUMPRODUCT((데이터!$A$2:$A$200=2)*(데이터!$B$2:$B$200=3)*데이터!$F$2:$F$200) | G12: =IF(E12=0,"",E12+F12) | H12: =IF(E12=0,"",E12*0.15) | I12: =IF(E12=0,"",F12*0.13) | J12: =IF(E12=0,"",H12+I12) | K12: =IF(E12=0,"",J12*0.1) | L12: =IF(AND(E12<>0,B12=4),3000000,0) | M12: =IF(L12=0,0,L12*0.1) | N12: =IF(AND(E12<>0,B12=4),120900,0) | O12: =(SUMPRODUCT((데이터!$A$2:$A$200=2)*(데이터!$B$2:$B$200=3)*데이터!$G$2:$G$200)+SUMPRODUCT((데이터!$A$2:$A$200=2)*(데이터!$B$2:$B$200=3)*데이터!$H$2:$H$200)+SUMPRODUCT((데이터!$A$2:$A$200=2)*(데이터!$B$2:$B$200=3)*데이터!$I$2:$I$200))*0.95 | P12: =SUMPRODUCT((데이터!$A$2:$A$200=2)*(데이터!$B$2:$B$200=3)*데이터!$J$2:$J$200)+SUMPRODUCT((데이터!$A$2:$A$200=2)*(데이터!$B$2:$B$200=3)*데이터!$K$2:$K$200)*0.05+SUMPRODUCT((데이터!$A$2:$A$200=2)*(데이터!$B$2:$B$200=3)*데이터!$L$2:$L$200) | Q12: =IF(E12=0,"",J12+K12+L12+M12+N12+O12+P12) | R12: =IF(E12=0,"",E12-Q12) | S12: =IF(E12=0,"",F12-I12-I12*0.1) | T12: =IFERROR(INDEX(데이터!$M$2:$M$200,MATCH(1,(데이터!$A$2:$A$200=2)*(데이터!$B$2:$B$200=3),0)),"")
A13: 2 | B13: 4 | C13: =IFERROR(SUMPRODUCT((데이터!$A$2:$A$200=2)*(데이터!$B$2:$B$200=4)*데이터!$C$2:$C$200),"") | D13: =IFERROR(SUMPRODUCT((데이터!$A$2:$A$200=2)*(데이터!$B$2:$B$200=4)*데이터!$D$2:$D$200),"") | E13: =SUMPRODUCT((데이터!$A$2:$A$200=2)*(데이터!$B$2:$B$200=4)*데이터!$E$2:$E$200) | F13: =SUMPRODUCT((데이터!$A$2:$A$200=2)*(데이터!$B$2:$B$200=4)*데이터!$F$2:$F$200) | G13: =IF(E13=0,"",E13+F13) | H13: =IF(E13=0,"",E13*0.15) | I13: =IF(E13=0,"",F13*0.13) | J13: =IF(E13=0,"",H13+I13) | K13: =IF(E13=0,"",J13*0.1) | L13: =IF(AND(E13<>0,B13=4),3000000,0) | M13: =IF(L13=0,0,L13*0.1) | N13: =IF(AND(E13<>0,B13=4),120900,0) | O13: =(SUMPRODUCT((데이터!$A$2:$A$200=2)*(데이터!$B$2:$B$200=4)*데이터!$G$2:$G$200)+SUMPRODUCT((데이터!$A$2:$A$200=2)*(데이터!$B$2:$B$200=4)*데이터!$H$2:$H$200)+SUMPRODUCT((데이터!$A$2:$A$200=2)*(데이터!$B$2:$B$200=4)*데이터!$I$2:$I$200))*0.95 | P13: =SUMPRODUCT((데이터!$A$2:$A$200=2)*(데이터!$B$2:$B$200=4)*데이터!$J$2:$J$200)+SUMPRODUCT((데이터!$A$2:$A$200=2)*(데이터!$B$2:$B$200=4)*데이터!$K$2:$K$200)*0.05+SUMPRODUCT((데이터!$A$2:$A$200=2)*(데이터!$B$2:$B$200=4)*데이터!$L$2:$L$200) | Q13: =IF(E13=0,"",J13+K13+L13+M13+N13+O13+P13) | R13: =IF(E13=0,"",E13-Q13) | S13: =IF(E13=0,"",F13-I13-I13*0.1) | T13: =IFERROR(INDEX(데이터!$M$2:$M$200,MATCH(1,(데이터!$A$2:$A$200=2)*(데이터!$B$2:$B$200=4),0)),"")
A14: 2 | B14: 5 | C14: =IFERROR(SUMPRODUCT((데이터!$A$2:$A$200=2)*(데이터!$B$2:$B$200=5)*데이터!$C$2:$C$200),"") | D14: =IFERROR(SUMPRODUCT((데이터!$A$2:$A$200=2)*(데이터!$B$2:$B$200=5)*데이터!$D$2:$D$200),"") | E14: =SUMPRODUCT((데이터!$A$2:$A$200=2)*(데이터!$B$2:$B$200=5)*데이터!$E$2:$E$200) | F14: =SUMPRODUCT((데이터!$A$2:$A$200=2)*(데이터!$B$2:$B$200=5)*데이터!$F$2:$F$200) | G14: =IF(E14=0,"",E14+F14) | H14: =IF(E14=0,"",E14*0.15) | I14: =IF(E14=0,"",F14*0.13) | J14: =IF(E14=0,"",H14+I14) | K14: =IF(E14=0,"",J14*0.1) | L14: =IF(AND(E14<>0,B14=4),3000000,0) | M14: =IF(L14=0,0,L14*0.1) | N14: =IF(AND(E14<>0,B14=4),120900,0) | O14: =(SUMPRODUCT((데이터!$A$2:$A$200=2)*(데이터!$B$2:$B$200=5)*데이터!$G$2:$G$200)+SUMPRODUCT((데이터!$A$2:$A$200=2)*(데이터!$B$2:$B$200=5)*데이터!$H$2:$H$200)+SUMPRODUCT((데이터!$A$2:$A$200=2)*(데이터!$B$2:$B$200=5)*데이터!$I$2:$I$200))*0.95 | P14: =SUMPRODUCT((데이터!$A$2:$A$200=2)*(데이터!$B$2:$B$200=5)*데이터!$J$2:$J$200)+SUMPRODUCT((데이터!$A$2:$A$200=2)*(데이터!$B$2:$B$200=5)*데이터!$K$2:$K$200)*0.05+SUMPRODUCT((데이터!$A$2:$A$200=2)*(데이터!$B$2:$B$200=5)*데이터!$L$2:$L$200) | Q14: =IF(E14=0,"",J14+K14+L14+M14+N14+O14+P14) | R14: =IF(E14=0,"",E14-Q14) | S14: =IF(E14=0,"",F14-I14-I14*0.1) | T14: =IFERROR(INDEX(데이터!$M$2:$M$200,MATCH(1,(데이터!$A$2:$A$200=2)*(데이터!$B$2:$B$200=5),0)),"")
A15: 2월 | B15: 소계 | E15: =SUM(E10:E14) | F15: =SUM(F10:F14) | G15: =SUM(G10:G14) | H15: =SUM(H10:H14) | I15: =SUM(I10:I14) | J15: =SUM(J10:J14) | K15: =SUM(K10:K14) | L15: =SUM(L10:L14) | ... S15: =SUM(S10:S14)
A16: 3 | B16: 1 | C16: =IFERROR(SUMPRODUCT((데이터!$A$2:$A$200=3)*(데이터!$B$2:$B$200=1)*데이터!$C$2:$C$200),"") | D16: =IFERROR(SUMPRODUCT((데이터!$A$2:$A$200=3)*(데이터!$B$2:$B$200=1)*데이터!$D$2:$D$200),"") | E16: =SUMPRODUCT((데이터!$A$2:$A$200=3)*(데이터!$B$2:$B$200=1)*데이터!$E$2:$E$200) | F16: =SUMPRODUCT((데이터!$A$2:$A$200=3)*(데이터!$B$2:$B$200=1)*데이터!$F$2:$F$200) | G16: =IF(E16=0,"",E16+F16) | H16: =IF(E16=0,"",E16*0.15) | I16: =IF(E16=0,"",F16*0.13) | J16: =IF(E16=0,"",H16+I16) | K16: =IF(E16=0,"",J16*0.1) | L16: =IF(AND(E16<>0,B16=4),3000000,0) | M16: =IF(L16=0,0,L16*0.1) | N16: =IF(AND(E16<>0,B16=4),120900,0) | O16: =(SUMPRODUCT((데이터!$A$2:$A$200=3)*(데이터!$B$2:$B$200=1)*데이터!$G$2:$G$200)+SUMPRODUCT((데이터!$A$2:$A$200=3)*(데이터!$B$2:$B$200=1)*데이터!$H$2:$H$200)+SUMPRODUCT((데이터!$A$2:$A$200=3)*(데이터!$B$2:$B$200=1)*데이터!$I$2:$I$200))*0.95 | P16: =SUMPRODUCT((데이터!$A$2:$A$200=3)*(데이터!$B$2:$B$200=1)*데이터!$J$2:$J$200)+SUMPRODUCT((데이터!$A$2:$A$200=3)*(데이터!$B$2:$B$200=1)*데이터!$K$2:$K$200)*0.05+SUMPRODUCT((데이터!$A$2:$A$200=3)*(데이터!$B$2:$B$200=1)*데이터!$L$2:$L$200) | Q16: =IF(E16=0,"",J16+K16+L16+M16+N16+O16+P16) | R16: =IF(E16=0,"",E16-Q16) | S16: =IF(E16=0,"",F16-I16-I16*0.1) | T16: =IFERROR(INDEX(데이터!$M$2:$M$200,MATCH(1,(데이터!$A$2:$A$200=3)*(데이터!$B$2:$B$200=1),0)),"")
A17: 3 | B17: 2 | C17: =IFERROR(SUMPRODUCT((데이터!$A$2:$A$200=3)*(데이터!$B$2:$B$200=2)*데이터!$C$2:$C$200),"") | D17: =IFERROR(SUMPRODUCT((데이터!$A$2:$A$200=3)*(데이터!$B$2:$B$200=2)*데이터!$D$2:$D$200),"") | E17: =SUMPRODUCT((데이터!$A$2:$A$200=3)*(데이터!$B$2:$B$200=2)*데이터!$E$2:$E$200) | F17: =SUMPRODUCT((데이터!$A$2:$A$200=3)*(데이터!$B$2:$B$200=2)*데이터!$F$2:$F$200) | G17: =IF(E17=0,"",E17+F17) | H17: =IF(E17=0,"",E17*0.15) | I17: =IF(E17=0,"",F17*0.13) | J17: =IF(E17=0,"",H17+I17) | K17: =IF(E17=0,"",J17*0.1) | L17: =IF(AND(E17<>0,B17=4),3000000,0) | M17: =IF(L17=0,0,L17*0.1) | N17: =IF(AND(E17<>0,B17=4),120900,0) | O17: =(SUMPRODUCT((데이터!$A$2:$A$200=3)*(데이터!$B$2:$B$200=2)*데이터!$G$2:$G$200)+SUMPRODUCT((데이터!$A$2:$A$200=3)*(데이터!$B$2:$B$200=2)*데이터!$H$2:$H$200)+SUMPRODUCT((데이터!$A$2:$A$200=3)*(데이터!$B$2:$B$200=2)*데이터!$I$2:$I$200))*0.95 | P17: =SUMPRODUCT((데이터!$A$2:$A$200=3)*(데이터!$B$2:$B$200=2)*데이터!$J$2:$J$200)+SUMPRODUCT((데이터!$A$2:$A$200=3)*(데이터!$B$2:$B$200=2)*데이터!$K$2:$K$200)*0.05+SUMPRODUCT((데이터!$A$2:$A$200=3)*(데이터!$B$2:$B$200=2)*데이터!$L$2:$L$200) | Q17: =IF(E17=0,"",J17+K17+L17+M17+N17+O17+P17) | R17: =IF(E17=0,"",E17-Q17) | S17: =IF(E17=0,"",F17-I17-I17*0.1) | T17: =IFERROR(INDEX(데이터!$M$2:$M$200,MATCH(1,(데이터!$A$2:$A$200=3)*(데이터!$B$2:$B$200=2),0)),"")
A18: 3 | B18: 3 | C18: =IFERROR(SUMPRODUCT((데이터!$A$2:$A$200=3)*(데이터!$B$2:$B$200=3)*데이터!$C$2:$C$200),"") | D18: =IFERROR(SUMPRODUCT((데이터!$A$2:$A$200=3)*(데이터!$B$2:$B$200=3)*데이터!$D$2:$D$200),"") | E18: =SUMPRODUCT((데이터!$A$2:$A$200=3)*(데이터!$B$2:$B$200=3)*데이터!$E$2:$E$200) | F18: =SUMPRODUCT((데이터!$A$2:$A$200=3)*(데이터!$B$2:$B$200=3)*데이터!$F$2:$F$200) | G18: =IF(E18=0,"",E18+F18) | H18: =IF(E18=0,"",E18*0.15) | I18: =IF(E18=0,"",F18*0.13) | J18: =IF(E18=0,"",H18+I18) | K18: =IF(E18=0,"",J18*0.1) | L18: =IF(AND(E18<>0,B18=4),3000000,0) | M18: =IF(L18=0,0,L18*0.1) | N18: =IF(AND(E18<>0,B18=4),120900,0) | O18: =(SUMPRODUCT((데이터!$A$2:$A$200=3)*(데이터!$B$2:$B$200=3)*데이터!$G$2:$G$200)+SUMPRODUCT((데이터!$A$2:$A$200=3)*(데이터!$B$2:$B$200=3)*데이터!$H$2:$H$200)+SUMPRODUCT((데이터!$A$2:$A$200=3)*(데이터!$B$2:$B$200=3)*데이터!$I$2:$I$200))*0.95 | P18: =SUMPRODUCT((데이터!$A$2:$A$200=3)*(데이터!$B$2:$B$200=3)*데이터!$J$2:$J$200)+SUMPRODUCT((데이터!$A$2:$A$200=3)*(데이터!$B$2:$B$200=3)*데이터!$K$2:$K$200)*0.05+SUMPRODUCT((데이터!$A$2:$A$200=3)*(데이터!$B$2:$B$200=3)*데이터!$L$2:$L$200) | Q18: =IF(E18=0,"",J18+K18+L18+M18+N18+O18+P18) | R18: =IF(E18=0,"",E18-Q18) | S18: =IF(E18=0,"",F18-I18-I18*0.1) | T18: =IFERROR(INDEX(데이터!$M$2:$M$200,MATCH(1,(데이터!$A$2:$A$200=3)*(데이터!$B$2:$B$200=3),0)),"")
A19: 3 | B19: 4 | C19: =IFERROR(SUMPRODUCT((데이터!$A$2:$A$200=3)*(데이터!$B$2:$B$200=4)*데이터!$C$2:$C$200),"") | D19: =IFERROR(SUMPRODUCT((데이터!$A$2:$A$200=3)*(데이터!$B$2:$B$200=4)*데이터!$D$2:$D$200),"") | E19: =SUMPRODUCT((데이터!$A$2:$A$200=3)*(데이터!$B$2:$B$200=4)*데이터!$E$2:$E$200) | F19: =SUMPRODUCT((데이터!$A$2:$A$200=3)*(데이터!$B$2:$B$200=4)*데이터!$F$2:$F$200) | G19: =IF(E19=0,"",E19+F19) | H19: =IF(E19=0,"",E19*0.15) | I19: =IF(E19=0,"",F19*0.13) | J19: =IF(E19=0,"",H19+I19) | K19: =IF(E19=0,"",J19*0.1) | L19: =IF(AND(E19<>0,B19=4),3000000,0) | M19: =IF(L19=0,0,L19*0.1) | N19: =IF(AND(E19<>0,B19=4),120900,0) | O19: =(SUMPRODUCT((데이터!$A$2:$A$200=3)*(데이터!$B$2:$B$200=4)*데이터!$G$2:$G$200)+SUMPRODUCT((데이터!$A$2:$A$200=3)*(데이터!$B$2:$B$200=4)*데이터!$H$2:$H$200)+SUMPRODUCT((데이터!$A$2:$A$200=3)*(데이터!$B$2:$B$200=4)*데이터!$I$2:$I$200))*0.95 | P19: =SUMPRODUCT((데이터!$A$2:$A$200=3)*(데이터!$B$2:$B$200=4)*데이터!$J$2:$J$200)+SUMPRODUCT((데이터!$A$2:$A$200=3)*(데이터!$B$2:$B$200=4)*데이터!$K$2:$K$200)*0.05+SUMPRODUCT((데이터!$A$2:$A$200=3)*(데이터!$B$2:$B$200=4)*데이터!$L$2:$L$200) | Q19: =IF(E19=0,"",J19+K19+L19+M19+N19+O19+P19) | R19: =IF(E19=0,"",E19-Q19) | S19: =IF(E19=0,"",F19-I19-I19*0.1) | T19: =IFERROR(INDEX(데이터!$M$2:$M$200,MATCH(1,(데이터!$A$2:$A$200=3)*(데이터!$B$2:$B$200=4),0)),"")
A20: 3 | B20: 5 | C20: =IFERROR(SUMPRODUCT((데이터!$A$2:$A$200=3)*(데이터!$B$2:$B$200=5)*데이터!$C$2:$C$200),"") | D20: =IFERROR(SUMPRODUCT((데이터!$A$2:$A$200=3)*(데이터!$B$2:$B$200=5)*데이터!$D$2:$D$200),"") | E20: =SUMPRODUCT((데이터!$A$2:$A$200=3)*(데이터!$B$2:$B$200=5)*데이터!$E$2:$E$200) | F20: =SUMPRODUCT((데이터!$A$2:$A$200=3)*(데이터!$B$2:$B$200=5)*데이터!$F$2:$F$200) | G20: =IF(E20=0,"",E20+F20) | H20: =IF(E20=0,"",E20*0.15) | I20: =IF(E20=0,"",F20*0.13) | J20: =IF(E20=0,"",H20+I20) | K20: =IF(E20=0,"",J20*0.1) | L20: =IF(AND(E20<>0,B20=4),3000000,0) | M20: =IF(L20=0,0,L20*0.1) | N20: =IF(AND(E20<>0,B20=4),120900,0) | O20: =(SUMPRODUCT((데이터!$A$2:$A$200=3)*(데이터!$B$2:$B$200=5)*데이터!$G$2:$G$200)+SUMPRODUCT((데이터!$A$2:$A$200=3)*(데이터!$B$2:$B$200=5)*데이터!$H$2:$H$200)+SUMPRODUCT((데이터!$A$2:$A$200=3)*(데이터!$B$2:$B$200=5)*데이터!$I$2:$I$200))*0.95 | P20: =SUMPRODUCT((데이터!$A$2:$A$200=3)*(데이터!$B$2:$B$200=5)*데이터!$J$2:$J$200)+SUMPRODUCT((데이터!$A$2:$A$200=3)*(데이터!$B$2:$B$200=5)*데이터!$K$2:$K$200)*0.05+SUMPRODUCT((데이터!$A$2:$A$200=3)*(데이터!$B$2:$B$200=5)*데이터!$L$2:$L$200) | Q20: =IF(E20=0,"",J20+K20+L20+M20+N20+O20+P20) | R20: =IF(E20=0,"",E20-Q20) | S20: =IF(E20=0,"",F20-I20-I20*0.1) | T20: =IFERROR(INDEX(데이터!$M$2:$M$200,MATCH(1,(데이터!$A$2:$A$200=3)*(데이터!$B$2:$B$200=5),0)),"")
A21: 3월 | B21: 소계 | E21: =SUM(E16:E20) | F21: =SUM(F16:F20) | G21: =SUM(G16:G20) | H21: =SUM(H16:H20) | I21: =SUM(I16:I20) | J21: =SUM(J16:J20) | K21: =SUM(K16:K20) | L21: =SUM(L16:L20) | ... S21: =SUM(S16:S20)
A22: 4 | B22: 1 | C22: =IFERROR(SUMPRODUCT((데이터!$A$2:$A$200=4)*(데이터!$B$2:$B$200=1)*데이터!$C$2:$C$200),"") | D22: =IFERROR(SUMPRODUCT((데이터!$A$2:$A$200=4)*(데이터!$B$2:$B$200=1)*데이터!$D$2:$D$200),"") | E22: =SUMPRODUCT((데이터!$A$2:$A$200=4)*(데이터!$B$2:$B$200=1)*데이터!$E$2:$E$200) | F22: =SUMPRODUCT((데이터!$A$2:$A$200=4)*(데이터!$B$2:$B$200=1)*데이터!$F$2:$F$200) | G22: =IF(E22=0,"",E22+F22) | H22: =IF(E22=0,"",E22*0.15) | I22: =IF(E22=0,"",F22*0.13) | J22: =IF(E22=0,"",H22+I22) | K22: =IF(E22=0,"",J22*0.1) | L22: =IF(AND(E22<>0,B22=4),3000000,0) | M22: =IF(L22=0,0,L22*0.1) | N22: =IF(AND(E22<>0,B22=4),120900,0) | O22: =(SUMPRODUCT((데이터!$A$2:$A$200=4)*(데이터!$B$2:$B$200=1)*데이터!$G$2:$G$200)+SUMPRODUCT((데이터!$A$2:$A$200=4)*(데이터!$B$2:$B$200=1)*데이터!$H$2:$H$200)+SUMPRODUCT((데이터!$A$2:$A$200=4)*(데이터!$B$2:$B$200=1)*데이터!$I$2:$I$200))*0.95 | P22: =SUMPRODUCT((데이터!$A$2:$A$200=4)*(데이터!$B$2:$B$200=1)*데이터!$J$2:$J$200)+SUMPRODUCT((데이터!$A$2:$A$200=4)*(데이터!$B$2:$B$200=1)*데이터!$K$2:$K$200)*0.05+SUMPRODUCT((데이터!$A$2:$A$200=4)*(데이터!$B$2:$B$200=1)*데이터!$L$2:$L$200) | Q22: =IF(E22=0,"",J22+K22+L22+M22+N22+O22+P22) | R22: =IF(E22=0,"",E22-Q22) | S22: =IF(E22=0,"",F22-I22-I22*0.1) | T22: =IFERROR(INDEX(데이터!$M$2:$M$200,MATCH(1,(데이터!$A$2:$A$200=4)*(데이터!$B$2:$B$200=1),0)),"")
A23: 4 | B23: 2 | C23: =IFERROR(SUMPRODUCT((데이터!$A$2:$A$200=4)*(데이터!$B$2:$B$200=2)*데이터!$C$2:$C$200),"") | D23: =IFERROR(SUMPRODUCT((데이터!$A$2:$A$200=4)*(데이터!$B$2:$B$200=2)*데이터!$D$2:$D$200),"") | E23: =SUMPRODUCT((데이터!$A$2:$A$200=4)*(데이터!$B$2:$B$200=2)*데이터!$E$2:$E$200) | F23: =SUMPRODUCT((데이터!$A$2:$A$200=4)*(데이터!$B$2:$B$200=2)*데이터!$F$2:$F$200) | G23: =IF(E23=0,"",E23+F23) | H23: =IF(E23=0,"",E23*0.15) | I23: =IF(E23=0,"",F23*0.13) | J23: =IF(E23=0,"",H23+I23) | K23: =IF(E23=0,"",J23*0.1) | L23: =IF(AND(E23<>0,B23=4),3000000,0) | M23: =IF(L23=0,0,L23*0.1) | N23: =IF(AND(E23<>0,B23=4),120900,0) | O23: =(SUMPRODUCT((데이터!$A$2:$A$200=4)*(데이터!$B$2:$B$200=2)*데이터!$G$2:$G$200)+SUMPRODUCT((데이터!$A$2:$A$200=4)*(데이터!$B$2:$B$200=2)*데이터!$H$2:$H$200)+SUMPRODUCT((데이터!$A$2:$A$200=4)*(데이터!$B$2:$B$200=2)*데이터!$I$2:$I$200))*0.95 | P23: =SUMPRODUCT((데이터!$A$2:$A$200=4)*(데이터!$B$2:$B$200=2)*데이터!$J$2:$J$200)+SUMPRODUCT((데이터!$A$2:$A$200=4)*(데이터!$B$2:$B$200=2)*데이터!$K$2:$K$200)*0.05+SUMPRODUCT((데이터!$A$2:$A$200=4)*(데이터!$B$2:$B$200=2)*데이터!$L$2:$L$200) | Q23: =IF(E23=0,"",J23+K23+L23+M23+N23+O23+P23) | R23: =IF(E23=0,"",E23-Q23) | S23: =IF(E23=0,"",F23-I23-I23*0.1) | T23: =IFERROR(INDEX(데이터!$M$2:$M$200,MATCH(1,(데이터!$A$2:$A$200=4)*(데이터!$B$2:$B$200=2),0)),"")
A24: 4 | B24: 3 | C24: =IFERROR(SUMPRODUCT((데이터!$A$2:$A$200=4)*(데이터!$B$2:$B$200=3)*데이터!$C$2:$C$200),"") | D24: =IFERROR(SUMPRODUCT((데이터!$A$2:$A$200=4)*(데이터!$B$2:$B$200=3)*데이터!$D$2:$D$200),"") | E24: =SUMPRODUCT((데이터!$A$2:$A$200=4)*(데이터!$B$2:$B$200=3)*데이터!$E$2:$E$200) | F24: =SUMPRODUCT((데이터!$A$2:$A$200=4)*(데이터!$B$2:$B$200=3)*데이터!$F$2:$F$200) | G24: =IF(E24=0,"",E24+F24) | H24: =IF(E24=0,"",E24*0.15) | I24: =IF(E24=0,"",F24*0.13) | J24: =IF(E24=0,"",H24+I24) | K24: =IF(E24=0,"",J24*0.1) | L24: =IF(AND(E24<>0,B24=4),3000000,0) | M24: =IF(L24=0,0,L24*0.1) | N24: =IF(AND(E24<>0,B24=4),120900,0) | O24: =(SUMPRODUCT((데이터!$A$2:$A$200=4)*(데이터!$B$2:$B$200=3)*데이터!$G$2:$G$200)+SUMPRODUCT((데이터!$A$2:$A$200=4)*(데이터!$B$2:$B$200=3)*데이터!$H$2:$H$200)+SUMPRODUCT((데이터!$A$2:$A$200=4)*(데이터!$B$2:$B$200=3)*데이터!$I$2:$I$200))*0.95 | P24: =SUMPRODUCT((데이터!$A$2:$A$200=4)*(데이터!$B$2:$B$200=3)*데이터!$J$2:$J$200)+SUMPRODUCT((데이터!$A$2:$A$200=4)*(데이터!$B$2:$B$200=3)*데이터!$K$2:$K$200)*0.05+SUMPRODUCT((데이터!$A$2:$A$200=4)*(데이터!$B$2:$B$200=3)*데이터!$L$2:$L$200) | Q24: =IF(E24=0,"",J24+K24+L24+M24+N24+O24+P24) | R24: =IF(E24=0,"",E24-Q24) | S24: =IF(E24=0,"",F24-I24-I24*0.1) | T24: =IFERROR(INDEX(데이터!$M$2:$M$200,MATCH(1,(데이터!$A$2:$A$200=4)*(데이터!$B$2:$B$200=3),0)),"")
A25: 4 | B25: 4 | C25: =IFERROR(SUMPRODUCT((데이터!$A$2:$A$200=4)*(데이터!$B$2:$B$200=4)*데이터!$C$2:$C$200),"") | D25: =IFERROR(SUMPRODUCT((데이터!$A$2:$A$200=4)*(데이터!$B$2:$B$200=4)*데이터!$D$2:$D$200),"") | E25: =SUMPRODUCT((데이터!$A$2:$A$200=4)*(데이터!$B$2:$B$200=4)*데이터!$E$2:$E$200) | F25: =SUMPRODUCT((데이터!$A$2:$A$200=4)*(데이터!$B$2:$B$200=4)*데이터!$F$2:$F$200) | G25: =IF(E25=0,"",E25+F25) | H25: =IF(E25=0,"",E25*0.15) | I25: =IF(E25=0,"",F25*0.13) | J25: =IF(E25=0,"",H25+I25) | K25: =IF(E25=0,"",J25*0.1) | L25: =IF(AND(E25<>0,B25=4),3000000,0) | M25: =IF(L25=0,0,L25*0.1) | N25: =IF(AND(E25<>0,B25=4),120900,0) | O25: =(SUMPRODUCT((데이터!$A$2:$A$200=4)*(데이터!$B$2:$B$200=4)*데이터!$G$2:$G$200)+SUMPRODUCT((데이터!$A$2:$A$200=4)*(데이터!$B$2:$B$200=4)*데이터!$H$2:$H$200)+SUMPRODUCT((데이터!$A$2:$A$200=4)*(데이터!$B$2:$B$200=4)*데이터!$I$2:$I$200))*0.95 | P25: =SUMPRODUCT((데이터!$A$2:$A$200=4)*(데이터!$B$2:$B$200=4)*데이터!$J$2:$J$200)+SUMPRODUCT((데이터!$A$2:$A$200=4)*(데이터!$B$2:$B$200=4)*데이터!$K$2:$K$200)*0.05+SUMPRODUCT((데이터!$A$2:$A$200=4)*(데이터!$B$2:$B$200=4)*데이터!$L$2:$L$200) | Q25: =IF(E25=0,"",J25+K25+L25+M25+N25+O25+P25) | R25: =IF(E25=0,"",E25-Q25) | S25: =IF(E25=0,"",F25-I25-I25*0.1) | T25: =IFERROR(INDEX(데이터!$M$2:$M$200,MATCH(1,(데이터!$A$2:$A$200=4)*(데이터!$B$2:$B$200=4),0)),"")
A26: 4 | B26: 5 | C26: =IFERROR(SUMPRODUCT((데이터!$A$2:$A$200=4)*(데이터!$B$2:$B$200=5)*데이터!$C$2:$C$200),"") | D26: =IFERROR(SUMPRODUCT((데이터!$A$2:$A$200=4)*(데이터!$B$2:$B$200=5)*데이터!$D$2:$D$200),"") | E26: =SUMPRODUCT((데이터!$A$2:$A$200=4)*(데이터!$B$2:$B$200=5)*데이터!$E$2:$E$200) | F26: =SUMPRODUCT((데이터!$A$2:$A$200=4)*(데이터!$B$2:$B$200=5)*데이터!$F$2:$F$200) | G26: =IF(E26=0,"",E26+F26) | H26: =IF(E26=0,"",E26*0.15) | I26: =IF(E26=0,"",F26*0.13) | J26: =IF(E26=0,"",H26+I26) | K26: =IF(E26=0,"",J26*0.1) | L26: =IF(AND(E26<>0,B26=4),3000000,0) | M26: =IF(L26=0,0,L26*0.1) | N26: =IF(AND(E26<>0,B26=4),120900,0) | O26: =(SUMPRODUCT((데이터!$A$2:$A$200=4)*(데이터!$B$2:$B$200=5)*데이터!$G$2:$G$200)+SUMPRODUCT((데이터!$A$2:$A$200=4)*(데이터!$B$2:$B$200=5)*데이터!$H$2:$H$200)+SUMPRODUCT((데이터!$A$2:$A$200=4)*(데이터!$B$2:$B$200=5)*데이터!$I$2:$I$200))*0.95 | P26: =SUMPRODUCT((데이터!$A$2:$A$200=4)*(데이터!$B$2:$B$200=5)*데이터!$J$2:$J$200)+SUMPRODUCT((데이터!$A$2:$A$200=4)*(데이터!$B$2:$B$200=5)*데이터!$K$2:$K$200)*0.05+SUMPRODUCT((데이터!$A$2:$A$200=4)*(데이터!$B$2:$B$200=5)*데이터!$L$2:$L$200) | Q26: =IF(E26=0,"",J26+K26+L26+M26+N26+O26+P26) | R26: =IF(E26=0,"",E26-Q26) | S26: =IF(E26=0,"",F26-I26-I26*0.1) | T26: =IFERROR(INDEX(데이터!$M$2:$M$200,MATCH(1,(데이터!$A$2:$A$200=4)*(데이터!$B$2:$B$200=5),0)),"")
A27: 4월 | B27: 소계 | E27: =SUM(E22:E26) | F27: =SUM(F22:F26) | G27: =SUM(G22:G26) | H27: =SUM(H22:H26) | I27: =SUM(I22:I26) | J27: =SUM(J22:J26) | K27: =SUM(K22:K26) | L27: =SUM(L22:L26) | ... S27: =SUM(S22:S26)
A28: 5 | B28: 1 | C28: =IFERROR(SUMPRODUCT((데이터!$A$2:$A$200=5)*(데이터!$B$2:$B$200=1)*데이터!$C$2:$C$200),"") | D28: =IFERROR(SUMPRODUCT((데이터!$A$2:$A$200=5)*(데이터!$B$2:$B$200=1)*데이터!$D$2:$D$200),"") | E28: =SUMPRODUCT((데이터!$A$2:$A$200=5)*(데이터!$B$2:$B$200=1)*데이터!$E$2:$E$200) | F28: =SUMPRODUCT((데이터!$A$2:$A$200=5)*(데이터!$B$2:$B$200=1)*데이터!$F$2:$F$200) | G28: =IF(E28=0,"",E28+F28) | H28: =IF(E28=0,"",E28*0.15) | I28: =IF(E28=0,"",F28*0.13) | J28: =IF(E28=0,"",H28+I28) | K28: =IF(E28=0,"",J28*0.1) | L28: =IF(AND(E28<>0,B28=4),3000000,0) | M28: =IF(L28=0,0,L28*0.1) | N28: =IF(AND(E28<>0,B28=4),120900,0) | O28: =(SUMPRODUCT((데이터!$A$2:$A$200=5)*(데이터!$B$2:$B$200=1)*데이터!$G$2:$G$200)+SUMPRODUCT((데이터!$A$2:$A$200=5)*(데이터!$B$2:$B$200=1)*데이터!$H$2:$H$200)+SUMPRODUCT((데이터!$A$2:$A$200=5)*(데이터!$B$2:$B$200=1)*데이터!$I$2:$I$200))*0.95 | P28: =SUMPRODUCT((데이터!$A$2:$A$200=5)*(데이터!$B$2:$B$200=1)*데이터!$J$2:$J$200)+SUMPRODUCT((데이터!$A$2:$A$200=5)*(데이터!$B$2:$B$200=1)*데이터!$K$2:$K$200)*0.05+SUMPRODUCT((데이터!$A$2:$A$200=5)*(데이터!$B$2:$B$200=1)*데이터!$L$2:$L$200) | Q28: =IF(E28=0,"",J28+K28+L28+M28+N28+O28+P28) | R28: =IF(E28=0,"",E28-Q28) | S28: =IF(E28=0,"",F28-I28-I28*0.1) | T28: =IFERROR(INDEX(데이터!$M$2:$M$200,MATCH(1,(데이터!$A$2:$A$200=5)*(데이터!$B$2:$B$200=1),0)),"")
A29: 5 | B29: 2 | C29: =IFERROR(SUMPRODUCT((데이터!$A$2:$A$200=5)*(데이터!$B$2:$B$200=2)*데이터!$C$2:$C$200),"") | D29: =IFERROR(SUMPRODUCT((데이터!$A$2:$A$200=5)*(데이터!$B$2:$B$200=2)*데이터!$D$2:$D$200),"") | E29: =SUMPRODUCT((데이터!$A$2:$A$200=5)*(데이터!$B$2:$B$200=2)*데이터!$E$2:$E$200) | F29: =SUMPRODUCT((데이터!$A$2:$A$200=5)*(데이터!$B$2:$B$200=2)*데이터!$F$2:$F$200) | G29: =IF(E29=0,"",E29+F29) | H29: =IF(E29=0,"",E29*0.15) | I29: =IF(E29=0,"",F29*0.13) | J29: =IF(E29=0,"",H29+I29) | K29: =IF(E29=0,"",J29*0.1) | L29: =IF(AND(E29<>0,B29=4),3000000,0) | M29: =IF(L29=0,0,L29*0.1) | N29: =IF(AND(E29<>0,B29=4),120900,0) | O29: =(SUMPRODUCT((데이터!$A$2:$A$200=5)*(데이터!$B$2:$B$200=2)*데이터!$G$2:$G$200)+SUMPRODUCT((데이터!$A$2:$A$200=5)*(데이터!$B$2:$B$200=2)*데이터!$H$2:$H$200)+SUMPRODUCT((데이터!$A$2:$A$200=5)*(데이터!$B$2:$B$200=2)*데이터!$I$2:$I$200))*0.95 | P29: =SUMPRODUCT((데이터!$A$2:$A$200=5)*(데이터!$B$2:$B$200=2)*데이터!$J$2:$J$200)+SUMPRODUCT((데이터!$A$2:$A$200=5)*(데이터!$B$2:$B$200=2)*데이터!$K$2:$K$200)*0.05+SUMPRODUCT((데이터!$A$2:$A$200=5)*(데이터!$B$2:$B$200=2)*데이터!$L$2:$L$200) | Q29: =IF(E29=0,"",J29+K29+L29+M29+N29+O29+P29) | R29: =IF(E29=0,"",E29-Q29) | S29: =IF(E29=0,"",F29-I29-I29*0.1) | T29: =IFERROR(INDEX(데이터!$M$2:$M$200,MATCH(1,(데이터!$A$2:$A$200=5)*(데이터!$B$2:$B$200=2),0)),"")
A30: 5 | B30: 3 | C30: =IFERROR(SUMPRODUCT((데이터!$A$2:$A$200=5)*(데이터!$B$2:$B$200=3)*데이터!$C$2:$C$200),"") | D30: =IFERROR(SUMPRODUCT((데이터!$A$2:$A$200=5)*(데이터!$B$2:$B$200=3)*데이터!$D$2:$D$200),"") | E30: =SUMPRODUCT((데이터!$A$2:$A$200=5)*(데이터!$B$2:$B$200=3)*데이터!$E$2:$E$200) | F30: =SUMPRODUCT((데이터!$A$2:$A$200=5)*(데이터!$B$2:$B$200=3)*데이터!$F$2:$F$200) | G30: =IF(E30=0,"",E30+F30) | H30: =IF(E30=0,"",E30*0.15) | I30: =IF(E30=0,"",F30*0.13) | J30: =IF(E30=0,"",H30+I30) | K30: =IF(E30=0,"",J30*0.1) | L30: =IF(AND(E30<>0,B30=4),3000000,0) | M30: =IF(L30=0,0,L30*0.1) | N30: =IF(AND(E30<>0,B30=4),120900,0) | O30: =(SUMPRODUCT((데이터!$A$2:$A$200=5)*(데이터!$B$2:$B$200=3)*데이터!$G$2:$G$200)+SUMPRODUCT((데이터!$A$2:$A$200=5)*(데이터!$B$2:$B$200=3)*데이터!$H$2:$H$200)+SUMPRODUCT((데이터!$A$2:$A$200=5)*(데이터!$B$2:$B$200=3)*데이터!$I$2:$I$200))*0.95 | P30: =SUMPRODUCT((데이터!$A$2:$A$200=5)*(데이터!$B$2:$B$200=3)*데이터!$J$2:$J$200)+SUMPRODUCT((데이터!$A$2:$A$200=5)*(데이터!$B$2:$B$200=3)*데이터!$K$2:$K$200)*0.05+SUMPRODUCT((데이터!$A$2:$A$200=5)*(데이터!$B$2:$B$200=3)*데이터!$L$2:$L$200) | Q30: =IF(E30=0,"",J30+K30+L30+M30+N30+O30+P30) | R30: =IF(E30=0,"",E30-Q30) | S30: =IF(E30=0,"",F30-I30-I30*0.1) | T30: =IFERROR(INDEX(데이터!$M$2:$M$200,MATCH(1,(데이터!$A$2:$A$200=5)*(데이터!$B$2:$B$200=3),0)),"")
A31: 5 | B31: 4 | C31: =IFERROR(SUMPRODUCT((데이터!$A$2:$A$200=5)*(데이터!$B$2:$B$200=4)*데이터!$C$2:$C$200),"") | D31: =IFERROR(SUMPRODUCT((데이터!$A$2:$A$200=5)*(데이터!$B$2:$B$200=4)*데이터!$D$2:$D$200),"") | E31: =SUMPRODUCT((데이터!$A$2:$A$200=5)*(데이터!$B$2:$B$200=4)*데이터!$E$2:$E$200) | F31: =SUMPRODUCT((데이터!$A$2:$A$200=5)*(데이터!$B$2:$B$200=4)*데이터!$F$2:$F$200) | G31: =IF(E31=0,"",E31+F31) | H31: =IF(E31=0,"",E31*0.15) | I31: =IF(E31=0,"",F31*0.13) | J31: =IF(E31=0,"",H31+I31) | K31: =IF(E31=0,"",J31*0.1) | L31: =IF(AND(E31<>0,B31=4),3000000,0) | M31: =IF(L31=0,0,L31*0.1) | N31: =IF(AND(E31<>0,B31=4),120900,0) | O31: =(SUMPRODUCT((데이터!$A$2:$A$200=5)*(데이터!$B$2:$B$200=4)*데이터!$G$2:$G$200)+SUMPRODUCT((데이터!$A$2:$A$200=5)*(데이터!$B$2:$B$200=4)*데이터!$H$2:$H$200)+SUMPRODUCT((데이터!$A$2:$A$200=5)*(데이터!$B$2:$B$200=4)*데이터!$I$2:$I$200))*0.95 | P31: =SUMPRODUCT((데이터!$A$2:$A$200=5)*(데이터!$B$2:$B$200=4)*데이터!$J$2:$J$200)+SUMPRODUCT((데이터!$A$2:$A$200=5)*(데이터!$B$2:$B$200=4)*데이터!$K$2:$K$200)*0.05+SUMPRODUCT((데이터!$A$2:$A$200=5)*(데이터!$B$2:$B$200=4)*데이터!$L$2:$L$200) | Q31: =IF(E31=0,"",J31+K31+L31+M31+N31+O31+P31) | R31: =IF(E31=0,"",E31-Q31) | S31: =IF(E31=0,"",F31-I31-I31*0.1) | T31: =IFERROR(INDEX(데이터!$M$2:$M$200,MATCH(1,(데이터!$A$2:$A$200=5)*(데이터!$B$2:$B$200=4),0)),"")
A32: 5 | B32: 5 | C32: =IFERROR(SUMPRODUCT((데이터!$A$2:$A$200=5)*(데이터!$B$2:$B$200=5)*데이터!$C$2:$C$200),"") | D32: =IFERROR(SUMPRODUCT((데이터!$A$2:$A$200=5)*(데이터!$B$2:$B$200=5)*데이터!$D$2:$D$200),"") | E32: =SUMPRODUCT((데이터!$A$2:$A$200=5)*(데이터!$B$2:$B$200=5)*데이터!$E$2:$E$200) | F32: =SUMPRODUCT((데이터!$A$2:$A$200=5)*(데이터!$B$2:$B$200=5)*데이터!$F$2:$F$200) | G32: =IF(E32=0,"",E32+F32) | H32: =IF(E32=0,"",E32*0.15) | I32: =IF(E32=0,"",F32*0.13) | J32: =IF(E32=0,"",H32+I32) | K32: =IF(E32=0,"",J32*0.1) | L32: =IF(AND(E32<>0,B32=4),3000000,0) | M32: =IF(L32=0,0,L32*0.1) | N32: =IF(AND(E32<>0,B32=4),120900,0) | O32: =(SUMPRODUCT((데이터!$A$2:$A$200=5)*(데이터!$B$2:$B$200=5)*데이터!$G$2:$G$200)+SUMPRODUCT((데이터!$A$2:$A$200=5)*(데이터!$B$2:$B$200=5)*데이터!$H$2:$H$200)+SUMPRODUCT((데이터!$A$2:$A$200=5)*(데이터!$B$2:$B$200=5)*데이터!$I$2:$I$200))*0.95 | P32: =SUMPRODUCT((데이터!$A$2:$A$200=5)*(데이터!$B$2:$B$200=5)*데이터!$J$2:$J$200)+SUMPRODUCT((데이터!$A$2:$A$200=5)*(데이터!$B$2:$B$200=5)*데이터!$K$2:$K$200)*0.05+SUMPRODUCT((데이터!$A$2:$A$200=5)*(데이터!$B$2:$B$200=5)*데이터!$L$2:$L$200) | Q32: =IF(E32=0,"",J32+K32+L32+M32+N32+O32+P32) | R32: =IF(E32=0,"",E32-Q32) | S32: =IF(E32=0,"",F32-I32-I32*0.1) | T32: =IFERROR(INDEX(데이터!$M$2:$M$200,MATCH(1,(데이터!$A$2:$A$200=5)*(데이터!$B$2:$B$200=5),0)),"")
A33: 5월 | B33: 소계 | E33: =SUM(E28:E32) | F33: =SUM(F28:F32) | G33: =SUM(G28:G32) | H33: =SUM(H28:H32) | I33: =SUM(I28:I32) | J33: =SUM(J28:J32) | K33: =SUM(K28:K32) | L33: =SUM(L28:L32) | ... S33: =SUM(S28:S32)
A34: 6 | B34: 1 | C34: =IFERROR(SUMPRODUCT((데이터!$A$2:$A$200=6)*(데이터!$B$2:$B$200=1)*데이터!$C$2:$C$200),"") | D34: =IFERROR(SUMPRODUCT((데이터!$A$2:$A$200=6)*(데이터!$B$2:$B$200=1)*데이터!$D$2:$D$200),"") | E34: =SUMPRODUCT((데이터!$A$2:$A$200=6)*(데이터!$B$2:$B$200=1)*데이터!$E$2:$E$200) | F34: =SUMPRODUCT((데이터!$A$2:$A$200=6)*(데이터!$B$2:$B$200=1)*데이터!$F$2:$F$200) | G34: =IF(E34=0,"",E34+F34) | H34: =IF(E34=0,"",E34*0.15) | I34: =IF(E34=0,"",F34*0.13) | J34: =IF(E34=0,"",H34+I34) | K34: =IF(E34=0,"",J34*0.1) | L34: =IF(AND(E34<>0,B34=4),3000000,0) | M34: =IF(L34=0,0,L34*0.1) | N34: =IF(AND(E34<>0,B34=4),120900,0) | O34: =(SUMPRODUCT((데이터!$A$2:$A$200=6)*(데이터!$B$2:$B$200=1)*데이터!$G$2:$G$200)+SUMPRODUCT((데이터!$A$2:$A$200=6)*(데이터!$B$2:$B$200=1)*데이터!$H$2:$H$200)+SUMPRODUCT((데이터!$A$2:$A$200=6)*(데이터!$B$2:$B$200=1)*데이터!$I$2:$I$200))*0.95 | P34: =SUMPRODUCT((데이터!$A$2:$A$200=6)*(데이터!$B$2:$B$200=1)*데이터!$J$2:$J$200)+SUMPRODUCT((데이터!$A$2:$A$200=6)*(데이터!$B$2:$B$200=1)*데이터!$K$2:$K$200)*0.05+SUMPRODUCT((데이터!$A$2:$A$200=6)*(데이터!$B$2:$B$200=1)*데이터!$L$2:$L$200) | Q34: =IF(E34=0,"",J34+K34+L34+M34+N34+O34+P34) | R34: =IF(E34=0,"",E34-Q34) | S34: =IF(E34=0,"",F34-I34-I34*0.1) | T34: =IFERROR(INDEX(데이터!$M$2:$M$200,MATCH(1,(데이터!$A$2:$A$200=6)*(데이터!$B$2:$B$200=1),0)),"")
A35: 6 | B35: 2 | C35: =IFERROR(SUMPRODUCT((데이터!$A$2:$A$200=6)*(데이터!$B$2:$B$200=2)*데이터!$C$2:$C$200),"") | D35: =IFERROR(SUMPRODUCT((데이터!$A$2:$A$200=6)*(데이터!$B$2:$B$200=2)*데이터!$D$2:$D$200),"") | E35: =SUMPRODUCT((데이터!$A$2:$A$200=6)*(데이터!$B$2:$B$200=2)*데이터!$E$2:$E$200) | F35: =SUMPRODUCT((데이터!$A$2:$A$200=6)*(데이터!$B$2:$B$200=2)*데이터!$F$2:$F$200) | G35: =IF(E35=0,"",E35+F35) | H35: =IF(E35=0,"",E35*0.15) | I35: =IF(E35=0,"",F35*0.13) | J35: =IF(E35=0,"",H35+I35) | K35: =IF(E35=0,"",J35*0.1) | L35: =IF(AND(E35<>0,B35=4),3000000,0) | M35: =IF(L35=0,0,L35*0.1) | N35: =IF(AND(E35<>0,B35=4),120900,0) | O35: =(SUMPRODUCT((데이터!$A$2:$A$200=6)*(데이터!$B$2:$B$200=2)*데이터!$G$2:$G$200)+SUMPRODUCT((데이터!$A$2:$A$200=6)*(데이터!$B$2:$B$200=2)*데이터!$H$2:$H$200)+SUMPRODUCT((데이터!$A$2:$A$200=6)*(데이터!$B$2:$B$200=2)*데이터!$I$2:$I$200))*0.95 | P35: =SUMPRODUCT((데이터!$A$2:$A$200=6)*(데이터!$B$2:$B$200=2)*데이터!$J$2:$J$200)+SUMPRODUCT((데이터!$A$2:$A$200=6)*(데이터!$B$2:$B$200=2)*데이터!$K$2:$K$200)*0.05+SUMPRODUCT((데이터!$A$2:$A$200=6)*(데이터!$B$2:$B$200=2)*데이터!$L$2:$L$200) | Q35: =IF(E35=0,"",J35+K35+L35+M35+N35+O35+P35) | R35: =IF(E35=0,"",E35-Q35) | S35: =IF(E35=0,"",F35-I35-I35*0.1) | T35: =IFERROR(INDEX(데이터!$M$2:$M$200,MATCH(1,(데이터!$A$2:$A$200=6)*(데이터!$B$2:$B$200=2),0)),"")
A36: 6 | B36: 3 | C36: =IFERROR(SUMPRODUCT((데이터!$A$2:$A$200=6)*(데이터!$B$2:$B$200=3)*데이터!$C$2:$C$200),"") | D36: =IFERROR(SUMPRODUCT((데이터!$A$2:$A$200=6)*(데이터!$B$2:$B$200=3)*데이터!$D$2:$D$200),"") | E36: =SUMPRODUCT((데이터!$A$2:$A$200=6)*(데이터!$B$2:$B$200=3)*데이터!$E$2:$E$200) | F36: =SUMPRODUCT((데이터!$A$2:$A$200=6)*(데이터!$B$2:$B$200=3)*데이터!$F$2:$F$200) | G36: =IF(E36=0,"",E36+F36) | H36: =IF(E36=0,"",E36*0.15) | I36: =IF(E36=0,"",F36*0.13) | J36: =IF(E36=0,"",H36+I36) | K36: =IF(E36=0,"",J36*0.1) | L36: =IF(AND(E36<>0,B36=4),3000000,0) | M36: =IF(L36=0,0,L36*0.1) | N36: =IF(AND(E36<>0,B36=4),120900,0) | O36: =(SUMPRODUCT((데이터!$A$2:$A$200=6)*(데이터!$B$2:$B$200=3)*데이터!$G$2:$G$200)+SUMPRODUCT((데이터!$A$2:$A$200=6)*(데이터!$B$2:$B$200=3)*데이터!$H$2:$H$200)+SUMPRODUCT((데이터!$A$2:$A$200=6)*(데이터!$B$2:$B$200=3)*데이터!$I$2:$I$200))*0.95 | P36: =SUMPRODUCT((데이터!$A$2:$A$200=6)*(데이터!$B$2:$B$200=3)*데이터!$J$2:$J$200)+SUMPRODUCT((데이터!$A$2:$A$200=6)*(데이터!$B$2:$B$200=3)*데이터!$K$2:$K$200)*0.05+SUMPRODUCT((데이터!$A$2:$A$200=6)*(데이터!$B$2:$B$200=3)*데이터!$L$2:$L$200) | Q36: =IF(E36=0,"",J36+K36+L36+M36+N36+O36+P36) | R36: =IF(E36=0,"",E36-Q36) | S36: =IF(E36=0,"",F36-I36-I36*0.1) | T36: =IFERROR(INDEX(데이터!$M$2:$M$200,MATCH(1,(데이터!$A$2:$A$200=6)*(데이터!$B$2:$B$200=3),0)),"")
A37: 6 | B37: 4 | C37: =IFERROR(SUMPRODUCT((데이터!$A$2:$A$200=6)*(데이터!$B$2:$B$200=4)*데이터!$C$2:$C$200),"") | D37: =IFERROR(SUMPRODUCT((데이터!$A$2:$A$200=6)*(데이터!$B$2:$B$200=4)*데이터!$D$2:$D$200),"") | E37: =SUMPRODUCT((데이터!$A$2:$A$200=6)*(데이터!$B$2:$B$200=4)*데이터!$E$2:$E$200) | F37: =SUMPRODUCT((데이터!$A$2:$A$200=6)*(데이터!$B$2:$B$200=4)*데이터!$F$2:$F$200) | G37: =IF(E37=0,"",E37+F37) | H37: =IF(E37=0,"",E37*0.15) | I37: =IF(E37=0,"",F37*0.13) | J37: =IF(E37=0,"",H37+I37) | K37: =IF(E37=0,"",J37*0.1) | L37: =IF(AND(E37<>0,B37=4),3000000,0) | M37: =IF(L37=0,0,L37*0.1) | N37: =IF(AND(E37<>0,B37=4),120900,0) | O37: =(SUMPRODUCT((데이터!$A$2:$A$200=6)*(데이터!$B$2:$B$200=4)*데이터!$G$2:$G$200)+SUMPRODUCT((데이터!$A$2:$A$200=6)*(데이터!$B$2:$B$200=4)*데이터!$H$2:$H$200)+SUMPRODUCT((데이터!$A$2:$A$200=6)*(데이터!$B$2:$B$200=4)*데이터!$I$2:$I$200))*0.95 | P37: =SUMPRODUCT((데이터!$A$2:$A$200=6)*(데이터!$B$2:$B$200=4)*데이터!$J$2:$J$200)+SUMPRODUCT((데이터!$A$2:$A$200=6)*(데이터!$B$2:$B$200=4)*데이터!$K$2:$K$200)*0.05+SUMPRODUCT((데이터!$A$2:$A$200=6)*(데이터!$B$2:$B$200=4)*데이터!$L$2:$L$200) | Q37: =IF(E37=0,"",J37+K37+L37+M37+N37+O37+P37) | R37: =IF(E37=0,"",E37-Q37) | S37: =IF(E37=0,"",F37-I37-I37*0.1) | T37: =IFERROR(INDEX(데이터!$M$2:$M$200,MATCH(1,(데이터!$A$2:$A$200=6)*(데이터!$B$2:$B$200=4),0)),"")
A38: 6 | B38: 5 | C38: =IFERROR(SUMPRODUCT((데이터!$A$2:$A$200=6)*(데이터!$B$2:$B$200=5)*데이터!$C$2:$C$200),"") | D38: =IFERROR(SUMPRODUCT((데이터!$A$2:$A$200=6)*(데이터!$B$2:$B$200=5)*데이터!$D$2:$D$200),"") | E38: =SUMPRODUCT((데이터!$A$2:$A$200=6)*(데이터!$B$2:$B$200=5)*데이터!$E$2:$E$200) | F38: =SUMPRODUCT((데이터!$A$2:$A$200=6)*(데이터!$B$2:$B$200=5)*데이터!$F$2:$F$200) | G38: =IF(E38=0,"",E38+F38) | H38: =IF(E38=0,"",E38*0.15) | I38: =IF(E38=0,"",F38*0.13) | J38: =IF(E38=0,"",H38+I38) | K38: =IF(E38=0,"",J38*0.1) | L38: =IF(AND(E38<>0,B38=4),3000000,0) | M38: =IF(L38=0,0,L38*0.1) | N38: =IF(AND(E38<>0,B38=4),120900,0) | O38: =(SUMPRODUCT((데이터!$A$2:$A$200=6)*(데이터!$B$2:$B$200=5)*데이터!$G$2:$G$200)+SUMPRODUCT((데이터!$A$2:$A$200=6)*(데이터!$B$2:$B$200=5)*데이터!$H$2:$H$200)+SUMPRODUCT((데이터!$A$2:$A$200=6)*(데이터!$B$2:$B$200=5)*데이터!$I$2:$I$200))*0.95 | P38: =SUMPRODUCT((데이터!$A$2:$A$200=6)*(데이터!$B$2:$B$200=5)*데이터!$J$2:$J$200)+SUMPRODUCT((데이터!$A$2:$A$200=6)*(데이터!$B$2:$B$200=5)*데이터!$K$2:$K$200)*0.05+SUMPRODUCT((데이터!$A$2:$A$200=6)*(데이터!$B$2:$B$200=5)*데이터!$L$2:$L$200) | Q38: =IF(E38=0,"",J38+K38+L38+M38+N38+O38+P38) | R38: =IF(E38=0,"",E38-Q38) | S38: =IF(E38=0,"",F38-I38-I38*0.1) | T38: =IFERROR(INDEX(데이터!$M$2:$M$200,MATCH(1,(데이터!$A$2:$A$200=6)*(데이터!$B$2:$B$200=5),0)),"")
A39: 6월 | B39: 소계 | E39: =SUM(E34:E38) | F39: =SUM(F34:F38) | G39: =SUM(G34:G38) | H39: =SUM(H34:H38) | I39: =SUM(I34:I38) | J39: =SUM(J34:J38) | K39: =SUM(K34:K38) | L39: =SUM(L34:L38) | ... S39: =SUM(S34:S38)
A40: 7 | B40: 1 | C40: =IFERROR(SUMPRODUCT((데이터!$A$2:$A$200=7)*(데이터!$B$2:$B$200=1)*데이터!$C$2:$C$200),"") | D40: =IFERROR(SUMPRODUCT((데이터!$A$2:$A$200=7)*(데이터!$B$2:$B$200=1)*데이터!$D$2:$D$200),"") | E40: =SUMPRODUCT((데이터!$A$2:$A$200=7)*(데이터!$B$2:$B$200=1)*데이터!$E$2:$E$200) | F40: =SUMPRODUCT((데이터!$A$2:$A$200=7)*(데이터!$B$2:$B$200=1)*데이터!$F$2:$F$200) | G40: =IF(E40=0,"",E40+F40) | H40: =IF(E40=0,"",E40*0.15) | I40: =IF(E40=0,"",F40*0.13) | J40: =IF(E40=0,"",H40+I40) | K40: =IF(E40=0,"",J40*0.1) | L40: =IF(AND(E40<>0,B40=4),3000000,0) | M40: =IF(L40=0,0,L40*0.1) | N40: =IF(AND(E40<>0,B40=4),120900,0) | O40: =(SUMPRODUCT((데이터!$A$2:$A$200=7)*(데이터!$B$2:$B$200=1)*데이터!$G$2:$G$200)+SUMPRODUCT((데이터!$A$2:$A$200=7)*(데이터!$B$2:$B$200=1)*데이터!$H$2:$H$200)+SUMPRODUCT((데이터!$A$2:$A$200=7)*(데이터!$B$2:$B$200=1)*데이터!$I$2:$I$200))*0.95 | P40: =SUMPRODUCT((데이터!$A$2:$A$200=7)*(데이터!$B$2:$B$200=1)*데이터!$J$2:$J$200)+SUMPRODUCT((데이터!$A$2:$A$200=7)*(데이터!$B$2:$B$200=1)*데이터!$K$2:$K$200)*0.05+SUMPRODUCT((데이터!$A$2:$A$200=7)*(데이터!$B$2:$B$200=1)*데이터!$L$2:$L$200) | Q40: =IF(E40=0,"",J40+K40+L40+M40+N40+O40+P40) | R40: =IF(E40=0,"",E40-Q40) | S40: =IF(E40=0,"",F40-I40-I40*0.1) | T40: =IFERROR(INDEX(데이터!$M$2:$M$200,MATCH(1,(데이터!$A$2:$A$200=7)*(데이터!$B$2:$B$200=1),0)),"")
...

Sheet 대시보드
A1: 미식가의 주방 — 경영 대시보드 (2026년)
M2: 현재월 → | N2: 3
B3: 이번달 총매출 | E3: 이번달 수수료수익 | H3: 이번달 임대수익 | K3: 연간 누적매출
B4: =INDEX(D9:D20,N2) | E4: =INDEX(G9:G20,N2) | H4: =INDEX(H9:H20,N2)+INDEX(I9:I20,N2) | K4: =D21
A7: 📊 월별 정산 요약
A8: 월 | B8: 카드매출 | C8: 현금매출 | D8: 총매출 | E8: 카드수수료 | F8: 현금수수료 | G8: 수수료합계 | H8: 임대료 | I8: 관리비 | J8: 공과금 | K8: 총차감 | L8: 미식가지급 | M8: 현금수령
A9: 1월 | B9: ='정산 요약'!E9 | C9: ='정산 요약'!F9 | D9: ='정산 요약'!G9 | E9: ='정산 요약'!H9 | F9: ='정산 요약'!I9 | G9: ='정산 요약'!J9 | H9: ='정산 요약'!L9 | I9: ='정산 요약'!N9 | J9: ='정산 요약'!O9 | K9: ='정산 요약'!Q9 | L9: ='정산 요약'!R9 | M9: ='정산 요약'!S9
A10: 2월 | B10: ='정산 요약'!E15 | C10: ='정산 요약'!F15 | D10: ='정산 요약'!G15 | E10: ='정산 요약'!H15 | F10: ='정산 요약'!I15 | G10: ='정산 요약'!J15 | H10: ='정산 요약'!L15 | I10: ='정산 요약'!N15 | J10: ='정산 요약'!O15 | K10: ='정산 요약'!Q15 | L10: ='정산 요약'!R15 | M10: ='정산 요약'!S15
A11: 3월 | B11: ='정산 요약'!E21 | C11: ='정산 요약'!F21 | D11: ='정산 요약'!G21 | E11: ='정산 요약'!H21 | F11: ='정산 요약'!I21 | G11: ='정산 요약'!J21 | H11: ='정산 요약'!L21 | I11: ='정산 요약'!N21 | J11: ='정산 요약'!O21 | K11: ='정산 요약'!Q21 | L11: ='정산 요약'!R21 | M11: ='정산 요약'!S21
A12: 4월 | B12: ='정산 요약'!E27 | C12: ='정산 요약'!F27 | D12: ='정산 요약'!G27 | E12: ='정산 요약'!H27 | F12: ='정산 요약'!I27 | G12: ='정산 요약'!J27 | H12: ='정산 요약'!L27 | I12: ='정산 요약'!N27 | J12: ='정산 요약'!O27 | K12: ='정산 요약'!Q27 | L12: ='정산 요약'!R27 | M12: ='정산 요약'!S27
A13: 5월 | B13: ='정산 요약'!E33 | C13: ='정산 요약'!F33 | D13: ='정산 요약'!G33 | E13: ='정산 요약'!H33 | F13: ='정산 요약'!I33 | G13: ='정산 요약'!J33 | H13: ='정산 요약'!L33 | I13: ='정산 요약'!N33 | J13: ='정산 요약'!O33 | K13: ='정산 요약'!Q33 | L13: ='정산 요약'!R33 | M13: ='정산 요약'!S33
A14: 6월 | B14: ='정산 요약'!E39 | C14: ='정산 요약'!F39 | D14: ='정산 요약'!G39 | E14: ='정산 요약'!H39 | F14: ='정산 요약'!I39 | G14: ='정산 요약'!J39 | H14: ='정산 요약'!L39 | I14: ='정산 요약'!N39 | J14: ='정산 요약'!O39 | K14: ='정산 요약'!Q39 | L14: ='정산 요약'!R39 | M14: ='정산 요약'!S39
A15: 7월 | B15: ='정산 요약'!E45 | C15: ='정산 요약'!F45 | D15: ='정산 요약'!G45 | E15: ='정산 요약'!H45 | F15: ='정산 요약'!I45 | G15: ='정산 요약'!J45 | H15: ='정산 요약'!L45 | I15: ='정산 요약'!N45 | J15: ='정산 요약'!O45 | K15: ='정산 요약'!Q45 | L15: ='정산 요약'!R45 | M15: ='정산 요약'!S45
A16: 8월 | B16: ='정산 요약'!E51 | C16: ='정산 요약'!F51 | D16: ='정산 요약'!G51 | E16: ='정산 요약'!H51 | F16: ='정산 요약'!I51 | G16: ='정산 요약'!J51 | H16: ='정산 요약'!L51 | I16: ='정산 요약'!N51 | J16: ='정산 요약'!O51 | K16: ='정산 요약'!Q51 | L16: ='정산 요약'!R51 | M16: ='정산 요약'!S51
A17: 9월 | B17: ='정산 요약'!E57 | C17: ='정산 요약'!F57 | D17: ='정산 요약'!G57 | E17: ='정산 요약'!H57 | F17: ='정산 요약'!I57 | G17: ='정산 요약'!J57 | H17: ='정산 요약'!L57 | I17: ='정산 요약'!N57 | J17: ='정산 요약'!O57 | K17: ='정산 요약'!Q57 | L17: ='정산 요약'!R57 | M17: ='정산 요약'!S57
A18: 10월 | B18: ='정산 요약'!E63 | C18: ='정산 요약'!F63 | D18: ='정산 요약'!G63 | E18: ='정산 요약'!H63 | F18: ='정산 요약'!I63 | G18: ='정산 요약'!J63 | H18: ='정산 요약'!L63 | I18: ='정산 요약'!N63 | J18: ='정산 요약'!O63 | K18: ='정산 요약'!Q63 | L18: ='정산 요약'!R63 | M18: ='정산 요약'!S63
A19: 11월 | B19: ='정산 요약'!E69 | C19: ='정산 요약'!F69 | D19: ='정산 요약'!G69 | E19: ='정산 요약'!H69 | F19: ='정산 요약'!I69 | G19: ='정산 요약'!J69 | H19: ='정산 요약'!L69 | I19: ='정산 요약'!N69 | J19: ='정산 요약'!O69 | K19: ='정산 요약'!Q69 | L19: ='정산 요약'!R69 | M19: ='정산 요약'!S69
A20: 12월 | B20: ='정산 요약'!E75 | C20: ='정산 요약'!F75 | D20: ='정산 요약'!G75 | E20: ='정산 요약'!H75 | F20: ='정산 요약'!I75 | G20: ='정산 요약'!J75 | H20: ='정산 요약'!L75 | I20: ='정산 요약'!N75 | J20: ='정산 요약'!O75 | K20: ='정산 요약'!Q75 | L20: ='정산 요약'!R75 | M20: ='정산 요약'!S75
A21: 합계 | B21: =SUM(B9:B20) | C21: =SUM(C9:C20) | D21: =SUM(D9:D20) | E21: =SUM(E9:E20) | F21: =SUM(F9:F20) | G21: =SUM(G9:G20) | H21: =SUM(H9:H20) | I21: =SUM(I9:I20) | ... M21: =SUM(M9:M20)
A40: 수익 구성 데이터
A41: 카드수수료 | B41: =E21
A42: 현금수수료 | B42: =F21
A43: 임대료 | B43: =H21
A44: 관리비 | B44: =I21
A45: 공과금 | B45: =J21

Sheet 미수금 관리
A1: 미식가의 주방 — 미수금 관리
A2: 기존 미수금 현황 + 상환 계획
A3: # | B3: 항목 | C3: 원금 | D3: 차감 누적 | E3: 잔액 | F3: 이자 | G3: 상태 | H3: 비고
A4: 1 | B4: 공과금 미수 | C4: 26480630 | E4: =C4-IF(D4="",0,D4) | G4: 미수 | H4: 2024.4~2025.12 누적
A5: 2 | B5: 임대료 미수 | C5: 6600000 | E5: =C5-IF(D5="",0,D5) | G5: 미수
A6: 3 | B6: 현금매출 수수료 미수 | C6: 2303154 | E6: =C6-IF(D6="",0,D6) | G6: 미수
A7: 4 | B7: 관리비 미수 | C7: 2123763 | E7: =C7-IF(D7="",0,D7) | G7: 미수
A8: 5 | B8: 정수기 임대료 미수 | C8: 333900 | E8: =C8-IF(D8="",0,D8) | G8: 미수
A9: 6 | B9: 이자 (연 10%) | C9: 2766151 | E9: =C9-IF(D9="",0,D9) | G9: 미수 | H9: 지연이자율 연 10%
B10: 합계 | C10: =SUM(C4:C9) | D10: =SUM(D4:D9) | E10: =SUM(E4:E9) | F10: =SUM(F4:F9)
A12: 📋 미수금 차감 계획
A13: # | B13: 회차 | C13: 예정일 | D13: 차감금액 | E13: 차감 후 잔액 | H13: 비고
A14: 1 | B14: 1회차 | C14: 2026-03-02 | D14: 6000000 | E14: =E10-D14
A15: 2 | B15: 2회차 | C15: 2026-03-09 | D15: 6000000 | E15: =E14-D15
A16: 3 | B16: 3회차 | C16: 2026-03-16 | D16: 6000000 | E16: =E15-D16
A17: 4 | B17: 4회차 | C17: 2026-03-23 | D17: 6000000 | E17: =E16-D17
A18: 5 | B18: 5회차 | C18: 2026-03-30 | D18: 6000000 | E18: =E17-D18
A19: 6 | B19: 6회차 | C19: 2026-04-06 | D19: 6000000 | E19: =E18-D19
A20: 7 | B20: 7회차 | C20: 2026-04-20 | D20: 4607598 | E20: =E19-D20

Sheet 데이터
A1: 월 | B1: 주차 | C1: 시작일 | D1: 종료일 | E1: 카드매출 | F1: 현금매출 | G1: 전기요금 | H1: 가스요금 | I1: 수도요금 | J1: 정화조 | K1: 회식매출 | L1: 기타비용 | M1: 비고 | N1: 입력일시
