Workbook

Sheet 정산 입력
A1: 미식가의 주방 — 주간 정산표 (2026년)
A2: 🟡 노란색 = 직접 입력 | 회색 = 자동 계산 (수정 금지) | 🔵 파란색 = 월 소계
A3: 월 | B3: 주 | C3: 시작일 | D3: 종료일 | E3: 카드매출 | F3: 현금매출 | G3: 총매출 | H3: 카드수수료 (15%) | I3: 현금수수료 (13%) | J3: 수수료합계 | K3: 수수료 VAT | L3: 임대료 (주간배분) | M3: 임대료 VAT | N3: 관리비 (주간배분) | O3: 공과금 | P3: 캡스/넷 | Q3: 기타비용 | R3: 총 차감액 | S3: 미식가 카드지급 | T3: 현금 수령액 | U3: 비고
A4: 1 | B4: 1 | G4: =IF(E4="","",E4+F4) | H4: =IF(E4="","",E4*0.15) | I4: =IF(E4="","",IF(F4="",0,F4*0.13)) | J4: =IF(E4="","",H4+I4) | K4: =IF(E4="","",J4*0.1) | L4: =IF(E4="","",3000000/COUNTA(E4:E8)) | M4: =IF(E4="","",L4*0.1) | N4: =IF(E4="","",70900/COUNTA(E4:E8)) | P4: =IF(E4="","",IF(B4=1,50000,0)) | R4: =IF(E4="","",H4+I4+K4+L4+M4+N4+IF(O4="",0,O4)+P4+IF(Q4="",0,Q4)) | S4: =IF(E4="","",E4-(R4-I4*1.1)) | T4: =IF(E4="","",I4*1.1)
A5: 1 | B5: 2 | G5: =IF(E5="","",E5+F5) | H5: =IF(E5="","",E5*0.15) | I5: =IF(E5="","",IF(F5="",0,F5*0.13)) | J5: =IF(E5="","",H5+I5) | K5: =IF(E5="","",J5*0.1) | L5: =IF(E5="","",3000000/COUNTA(E4:E8)) | M5: =IF(E5="","",L5*0.1) | N5: =IF(E5="","",70900/COUNTA(E4:E8)) | P5: =IF(E5="","",IF(B5=1,50000,0)) | R5: =IF(E5="","",H5+I5+K5+L5+M5+N5+IF(O5="",0,O5)+P5+IF(Q5="",0,Q5)) | S5: =IF(E5="","",E5-(R5-I5*1.1)) | T5: =IF(E5="","",I5*1.1)
A6: 1 | B6: 3 | G6: =IF(E6="","",E6+F6) | H6: =IF(E6="","",E6*0.15) | I6: =IF(E6="","",IF(F6="",0,F6*0.13)) | J6: =IF(E6="","",H6+I6) | K6: =IF(E6="","",J6*0.1) | L6: =IF(E6="","",3000000/COUNTA(E4:E8)) | M6: =IF(E6="","",L6*0.1) | N6: =IF(E6="","",70900/COUNTA(E4:E8)) | P6: =IF(E6="","",IF(B6=1,50000,0)) | R6: =IF(E6="","",H6+I6+K6+L6+M6+N6+IF(O6="",0,O6)+P6+IF(Q6="",0,Q6)) | S6: =IF(E6="","",E6-(R6-I6*1.1)) | T6: =IF(E6="","",I6*1.1)
A7: 1 | B7: 4 | G7: =IF(E7="","",E7+F7) | H7: =IF(E7="","",E7*0.15) | I7: =IF(E7="","",IF(F7="",0,F7*0.13)) | J7: =IF(E7="","",H7+I7) | K7: =IF(E7="","",J7*0.1) | L7: =IF(E7="","",3000000/COUNTA(E4:E8)) | M7: =IF(E7="","",L7*0.1) | N7: =IF(E7="","",70900/COUNTA(E4:E8)) | P7: =IF(E7="","",IF(B7=1,50000,0)) | R7: =IF(E7="","",H7+I7+K7+L7+M7+N7+IF(O7="",0,O7)+P7+IF(Q7="",0,Q7)) | S7: =IF(E7="","",E7-(R7-I7*1.1)) | T7: =IF(E7="","",I7*1.1)
A8: 1 | B8: 5 | G8: =IF(E8="","",E8+F8) | H8: =IF(E8="","",E8*0.15) | I8: =IF(E8="","",IF(F8="",0,F8*0.13)) | J8: =IF(E8="","",H8+I8) | K8: =IF(E8="","",J8*0.1) | L8: =IF(E8="","",3000000/COUNTA(E4:E8)) | M8: =IF(E8="","",L8*0.1) | N8: =IF(E8="","",70900/COUNTA(E4:E8)) | P8: =IF(E8="","",IF(B8=1,50000,0)) | R8: =IF(E8="","",H8+I8+K8+L8+M8+N8+IF(O8="",0,O8)+P8+IF(Q8="",0,Q8)) | S8: =IF(E8="","",E8-(R8-I8*1.1)) | T8: =IF(E8="","",I8*1.1)
A9: 1월 | B9: 소계 | E9: =SUM(E4:E8) | F9: =SUM(F4:F8) | G9: =SUM(G4:G8) | H9: =SUM(H4:H8) | I9: =SUM(I4:I8) | J9: =SUM(J4:J8) | K9: =SUM(K4:K8) | L9: =SUM(L4:L8) | ... T9: =SUM(T4:T8)
A10: 2 | B10: 1 | G10: =IF(E10="","",E10+F10) | H10: =IF(E10="","",E10*0.15) | I10: =IF(E10="","",IF(F10="",0,F10*0.13)) | J10: =IF(E10="","",H10+I10) | K10: =IF(E10="","",J10*0.1) | L10: =IF(E10="","",3000000/COUNTA(E10:E14)) | M10: =IF(E10="","",L10*0.1) | N10: =IF(E10="","",70900/COUNTA(E10:E14)) | P10: =IF(E10="","",IF(B10=1,50000,0)) | R10: =IF(E10="","",H10+I10+K10+L10+M10+N10+IF(O10="",0,O10)+P10+IF(Q10="",0,Q10)) | S10: =IF(E10="","",E10-(R10-I10*1.1)) | T10: =IF(E10="","",I10*1.1)
A11: 2 | B11: 2 | G11: =IF(E11="","",E11+F11) | H11: =IF(E11="","",E11*0.15) | I11: =IF(E11="","",IF(F11="",0,F11*0.13)) | J11: =IF(E11="","",H11+I11) | K11: =IF(E11="","",J11*0.1) | L11: =IF(E11="","",3000000/COUNTA(E10:E14)) | M11: =IF(E11="","",L11*0.1) | N11: =IF(E11="","",70900/COUNTA(E10:E14)) | P11: =IF(E11="","",IF(B11=1,50000,0)) | R11: =IF(E11="","",H11+I11+K11+L11+M11+N11+IF(O11="",0,O11)+P11+IF(Q11="",0,Q11)) | S11: =IF(E11="","",E11-(R11-I11*1.1)) | T11: =IF(E11="","",I11*1.1)
A12: 2 | B12: 3 | G12: =IF(E12="","",E12+F12) | H12: =IF(E12="","",E12*0.15) | I12: =IF(E12="","",IF(F12="",0,F12*0.13)) | J12: =IF(E12="","",H12+I12) | K12: =IF(E12="","",J12*0.1) | L12: =IF(E12="","",3000000/COUNTA(E10:E14)) | M12: =IF(E12="","",L12*0.1) | N12: =IF(E12="","",70900/COUNTA(E10:E14)) | P12: =IF(E12="","",IF(B12=1,50000,0)) | R12: =IF(E12="","",H12+I12+K12+L12+M12+N12+IF(O12="",0,O12)+P12+IF(Q12="",0,Q12)) | S12: =IF(E12="","",E12-(R12-I12*1.1)) | T12: =IF(E12="","",I12*1.1)
A13: 2 | B13: 4 | G13: =IF(E13="","",E13+F13) | H13: =IF(E13="","",E13*0.15) | I13: =IF(E13="","",IF(F13="",0,F13*0.13)) | J13: =IF(E13="","",H13+I13) | K13: =IF(E13="","",J13*0.1) | L13: =IF(E13="","",3000000/COUNTA(E10:E14)) | M13: =IF(E13="","",L13*0.1) | N13: =IF(E13="","",70900/COUNTA(E10:E14)) | P13: =IF(E13="","",IF(B13=1,50000,0)) | R13: =IF(E13="","",H13+I13+K13+L13+M13+N13+IF(O13="",0,O13)+P13+IF(Q13="",0,Q13)) | S13: =IF(E13="","",E13-(R13-I13*1.1)) | T13: =IF(E13="","",I13*1.1)
A14: 2 | B14: 5 | G14: =IF(E14="","",E14+F14) | H14: =IF(E14="","",E14*0.15) | I14: =IF(E14="","",IF(F14="",0,F14*0.13)) | J14: =IF(E14="","",H14+I14) | K14: =IF(E14="","",J14*0.1) | L14: =IF(E14="","",3000000/COUNTA(E10:E14)) | M14: =IF(E14="","",L14*0.1) | N14: =IF(E14="","",70900/COUNTA(E10:E14)) | P14: =IF(E14="","",IF(B14=1,50000,0)) | R14: =IF(E14="","",H14+I14+K14+L14+M14+N14+IF(O14="",0,O14)+P14+IF(Q14="",0,Q14)) | S14: =IF(E14="","",E14-(R14-I14*1.1)) | T14: =IF(E14="","",I14*1.1)
A15: 2월 | B15: 소계 | E15: =SUM(E10:E14) | F15: =SUM(F10:F14) | G15: =SUM(G10:G14) | H15: =SUM(H10:H14) | I15: =SUM(I10:I14) | J15: =SUM(J10:J14) | K15: =SUM(K10:K14) | L15: =SUM(L10:L14) | ... T15: =SUM(T10:T14)
A16: 3 | B16: 1 | G16: =IF(E16="","",E16+F16) | H16: =IF(E16="","",E16*0.15) | I16: =IF(E16="","",IF(F16="",0,F16*0.13)) | J16: =IF(E16="","",H16+I16) | K16: =IF(E16="","",J16*0.1) | L16: =IF(E16="","",3000000/COUNTA(E16:E20)) | M16: =IF(E16="","",L16*0.1) | N16: =IF(E16="","",70900/COUNTA(E16:E20)) | P16: =IF(E16="","",IF(B16=1,50000,0)) | R16: =IF(E16="","",H16+I16+K16+L16+M16+N16+IF(O16="",0,O16)+P16+IF(Q16="",0,Q16)) | S16: =IF(E16="","",E16-(R16-I16*1.1)) | T16: =IF(E16="","",I16*1.1)
A17: 3 | B17: 2 | G17: =IF(E17="","",E17+F17) | H17: =IF(E17="","",E17*0.15) | I17: =IF(E17="","",IF(F17="",0,F17*0.13)) | J17: =IF(E17="","",H17+I17) | K17: =IF(E17="","",J17*0.1) | L17: =IF(E17="","",3000000/COUNTA(E16:E20)) | M17: =IF(E17="","",L17*0.1) | N17: =IF(E17="","",70900/COUNTA(E16:E20)) | P17: =IF(E17="","",IF(B17=1,50000,0)) | R17: =IF(E17="","",H17+I17+K17+L17+M17+N17+IF(O17="",0,O17)+P17+IF(Q17="",0,Q17)) | S17: =IF(E17="","",E17-(R17-I17*1.1)) | T17: =IF(E17="","",I17*1.1)
A18: 3 | B18: 3 | G18: =IF(E18="","",E18+F18) | H18: =IF(E18="","",E18*0.15) | I18: =IF(E18="","",IF(F18="",0,F18*0.13)) | J18: =IF(E18="","",H18+I18) | K18: =IF(E18="","",J18*0.1) | L18: =IF(E18="","",3000000/COUNTA(E16:E20)) | M18: =IF(E18="","",L18*0.1) | N18: =IF(E18="","",70900/COUNTA(E16:E20)) | P18: =IF(E18="","",IF(B18=1,50000,0)) | R18: =IF(E18="","",H18+I18+K18+L18+M18+N18+IF(O18="",0,O18)+P18+IF(Q18="",0,Q18)) | S18: =IF(E18="","",E18-(R18-I18*1.1)) | T18: =IF(E18="","",I18*1.1)
A19: 3 | B19: 4 | G19: =IF(E19="","",E19+F19) | H19: =IF(E19="","",E19*0.15) | I19: =IF(E19="","",IF(F19="",0,F19*0.13)) | J19: =IF(E19="","",H19+I19) | K19: =IF(E19="","",J19*0.1) | L19: =IF(E19="","",3000000/COUNTA(E16:E20)) | M19: =IF(E19="","",L19*0.1) | N19: =IF(E19="","",70900/COUNTA(E16:E20)) | P19: =IF(E19="","",IF(B19=1,50000,0)) | R19: =IF(E19="","",H19+I19+K19+L19+M19+N19+IF(O19="",0,O19)+P19+IF(Q19="",0,Q19)) | S19: =IF(E19="","",E19-(R19-I19*1.1)) | T19: =IF(E19="","",I19*1.1)
A20: 3 | B20: 5 | G20: =IF(E20="","",E20+F20) | H20: =IF(E20="","",E20*0.15) | I20: =IF(E20="","",IF(F20="",0,F20*0.13)) | J20: =IF(E20="","",H20+I20) | K20: =IF(E20="","",J20*0.1) | L20: =IF(E20="","",3000000/COUNTA(E16:E20)) | M20: =IF(E20="","",L20*0.1) | N20: =IF(E20="","",70900/COUNTA(E16:E20)) | P20: =IF(E20="","",IF(B20=1,50000,0)) | R20: =IF(E20="","",H20+I20+K20+L20+M20+N20+IF(O20="",0,O20)+P20+IF(Q20="",0,Q20)) | S20: =IF(E20="","",E20-(R20-I20*1.1)) | T20: =IF(E20="","",I20*1.1)
A21: 3월 | B21: 소계 | E21: =SUM(E16:E20) | F21: =SUM(F16:F20) | G21: =SUM(G16:G20) | H21: =SUM(H16:H20) | I21: =SUM(I16:I20) | J21: =SUM(J16:J20) | K21: =SUM(K16:K20) | L21: =SUM(L16:L20) | ... T21: =SUM(T16:T20)
A22: 4 | B22: 1 | G22: =IF(E22="","",E22+F22) | H22: =IF(E22="","",E22*0.15) | I22: =IF(E22="","",IF(F22="",0,F22*0.13)) | J22: =IF(E22="","",H22+I22) | K22: =IF(E22="","",J22*0.1) | L22: =IF(E22="","",3000000/COUNTA(E22:E26)) | M22: =IF(E22="","",L22*0.1) | N22: =IF(E22="","",70900/COUNTA(E22:E26)) | P22: =IF(E22="","",IF(B22=1,50000,0)) | R22: =IF(E22="","",H22+I22+K22+L22+M22+N22+IF(O22="",0,O22)+P22+IF(Q22="",0,Q22)) | S22: =IF(E22="","",E22-(R22-I22*1.1)) | T22: =IF(E22="","",I22*1.1)
A23: 4 | B23: 2 | G23: =IF(E23="","",E23+F23) | H23: =IF(E23="","",E23*0.15) | I23: =IF(E23="","",IF(F23="",0,F23*0.13)) | J23: =IF(E23="","",H23+I23) | K23: =IF(E23="","",J23*0.1) | L23: =IF(E23="","",3000000/COUNTA(E22:E26)) | M23: =IF(E23="","",L23*0.1) | N23: =IF(E23="","",70900/COUNTA(E22:E26)) | P23: =IF(E23="","",IF(B23=1,50000,0)) | R23: =IF(E23="","",H23+I23+K23+L23+M23+N23+IF(O23="",0,O23)+P23+IF(Q23="",0,Q23)) | S23: =IF(E23="","",E23-(R23-I23*1.1)) | T23: =IF(E23="","",I23*1.1)
A24: 4 | B24: 3 | G24: =IF(E24="","",E24+F24) | H24: =IF(E24="","",E24*0.15) | I24: =IF(E24="","",IF(F24="",0,F24*0.13)) | J24: =IF(E24="","",H24+I24) | K24: =IF(E24="","",J24*0.1) | L24: =IF(E24="","",3000000/COUNTA(E22:E26)) | M24: =IF(E24="","",L24*0.1) | N24: =IF(E24="","",70900/COUNTA(E22:E26)) | P24: =IF(E24="","",IF(B24=1,50000,0)) | R24: =IF(E24="","",H24+I24+K24+L24+M24+N24+IF(O24="",0,O24)+P24+IF(Q24="",0,Q24)) | S24: =IF(E24="","",E24-(R24-I24*1.1)) | T24: =IF(E24="","",I24*1.1)
A25: 4 | B25: 4 | G25: =IF(E25="","",E25+F25) | H25: =IF(E25="","",E25*0.15) | I25: =IF(E25="","",IF(F25="",0,F25*0.13)) | J25: =IF(E25="","",H25+I25) | K25: =IF(E25="","",J25*0.1) | L25: =IF(E25="","",3000000/COUNTA(E22:E26)) | M25: =IF(E25="","",L25*0.1) | N25: =IF(E25="","",70900/COUNTA(E22:E26)) | P25: =IF(E25="","",IF(B25=1,50000,0)) | R25: =IF(E25="","",H25+I25+K25+L25+M25+N25+IF(O25="",0,O25)+P25+IF(Q25="",0,Q25)) | S25: =IF(E25="","",E25-(R25-I25*1.1)) | T25: =IF(E25="","",I25*1.1)
A26: 4 | B26: 5 | G26: =IF(E26="","",E26+F26) | H26: =IF(E26="","",E26*0.15) | I26: =IF(E26="","",IF(F26="",0,F26*0.13)) | J26: =IF(E26="","",H26+I26) | K26: =IF(E26="","",J26*0.1) | L26: =IF(E26="","",3000000/COUNTA(E22:E26)) | M26: =IF(E26="","",L26*0.1) | N26: =IF(E26="","",70900/COUNTA(E22:E26)) | P26: =IF(E26="","",IF(B26=1,50000,0)) | R26: =IF(E26="","",H26+I26+K26+L26+M26+N26+IF(O26="",0,O26)+P26+IF(Q26="",0,Q26)) | S26: =IF(E26="","",E26-(R26-I26*1.1)) | T26: =IF(E26="","",I26*1.1)
A27: 4월 | B27: 소계 | E27: =SUM(E22:E26) | F27: =SUM(F22:F26) | G27: =SUM(G22:G26) | H27: =SUM(H22:H26) | I27: =SUM(I22:I26) | J27: =SUM(J22:J26) | K27: =SUM(K22:K26) | L27: =SUM(L22:L26) | ... T27: =SUM(T22:T26)
A28: 5 | B28: 1 | G28: =IF(E28="","",E28+F28) | H28: =IF(E28="","",E28*0.15) | I28: =IF(E28="","",IF(F28="",0,F28*0.13)) | J28: =IF(E28="","",H28+I28) | K28: =IF(E28="","",J28*0.1) | L28: =IF(E28="","",3000000/COUNTA(E28:E32)) | M28: =IF(E28="","",L28*0.1) | N28: =IF(E28="","",70900/COUNTA(E28:E32)) | P28: =IF(E28="","",IF(B28=1,50000,0)) | R28: =IF(E28="","",H28+I28+K28+L28+M28+N28+IF(O28="",0,O28)+P28+IF(Q28="",0,Q28)) | S28: =IF(E28="","",E28-(R28-I28*1.1)) | T28: =IF(E28="","",I28*1.1)
A29: 5 | B29: 2 | G29: =IF(E29="","",E29+F29) | H29: =IF(E29="","",E29*0.15) | I29: =IF(E29="","",IF(F29="",0,F29*0.13)) | J29: =IF(E29="","",H29+I29) | K29: =IF(E29="","",J29*0.1) | L29: =IF(E29="","",3000000/COUNTA(E28:E32)) | M29: =IF(E29="","",L29*0.1) | N29: =IF(E29="","",70900/COUNTA(E28:E32)) | P29: =IF(E29="","",IF(B29=1,50000,0)) | R29: =IF(E29="","",H29+I29+K29+L29+M29+N29+IF(O29="",0,O29)+P29+IF(Q29="",0,Q29)) | S29: =IF(E29="","",E29-(R29-I29*1.1)) | T29: =IF(E29="","",I29*1.1)
A30: 5 | B30: 3 | G30: =IF(E30="","",E30+F30) | H30: =IF(E30="","",E30*0.15) | I30: =IF(E30="","",IF(F30="",0,F30*0.13)) | J30: =IF(E30="","",H30+I30) | K30: =IF(E30="","",J30*0.1) | L30: =IF(E30="","",3000000/COUNTA(E28:E32)) | M30: =IF(E30="","",L30*0.1) | N30: =IF(E30="","",70900/COUNTA(E28:E32)) | P30: =IF(E30="","",IF(B30=1,50000,0)) | R30: =IF(E30="","",H30+I30+K30+L30+M30+N30+IF(O30="",0,O30)+P30+IF(Q30="",0,Q30)) | S30: =IF(E30="","",E30-(R30-I30*1.1)) | T30: =IF(E30="","",I30*1.1)
A31: 5 | B31: 4 | G31: =IF(E31="","",E31+F31) | H31: =IF(E31="","",E31*0.15) | I31: =IF(E31="","",IF(F31="",0,F31*0.13)) | J31: =IF(E31="","",H31+I31) | K31: =IF(E31="","",J31*0.1) | L31: =IF(E31="","",3000000/COUNTA(E28:E32)) | M31: =IF(E31="","",L31*0.1) | N31: =IF(E31="","",70900/COUNTA(E28:E32)) | P31: =IF(E31="","",IF(B31=1,50000,0)) | R31: =IF(E31="","",H31+I31+K31+L31+M31+N31+IF(O31="",0,O31)+P31+IF(Q31="",0,Q31)) | S31: =IF(E31="","",E31-(R31-I31*1.1)) | T31: =IF(E31="","",I31*1.1)
A32: 5 | B32: 5 | G32: =IF(E32="","",E32+F32) | H32: =IF(E32="","",E32*0.15) | I32: =IF(E32="","",IF(F32="",0,F32*0.13)) | J32: =IF(E32="","",H32+I32) | K32: =IF(E32="","",J32*0.1) | L32: =IF(E32="","",3000000/COUNTA(E28:E32)) | M32: =IF(E32="","",L32*0.1) | N32: =IF(E32="","",70900/COUNTA(E28:E32)) | P32: =IF(E32="","",IF(B32=1,50000,0)) | R32: =IF(E32="","",H32+I32+K32+L32+M32+N32+IF(O32="",0,O32)+P32+IF(Q32="",0,Q32)) | S32: =IF(E32="","",E32-(R32-I32*1.1)) | T32: =IF(E32="","",I32*1.1)
A33: 5월 | B33: 소계 | E33: =SUM(E28:E32) | F33: =SUM(F28:F32) | G33: =SUM(G28:G32) | H33: =SUM(H28:H32) | I33: =SUM(I28:I32) | J33: =SUM(J28:J32) | K33: =SUM(K28:K32) | L33: =SUM(L28:L32) | ... T33: =SUM(T28:T32)
A34: 6 | B34: 1 | G34: =IF(E34="","",E34+F34) | H34: =IF(E34="","",E34*0.15) | I34: =IF(E34="","",IF(F34="",0,F34*0.13)) | J34: =IF(E34="","",H34+I34) | K34: =IF(E34="","",J34*0.1) | L34: =IF(E34="","",3000000/COUNTA(E34:E38)) | M34: =IF(E34="","",L34*0.1) | N34: =IF(E34="","",70900/COUNTA(E34:E38)) | P34: =IF(E34="","",IF(B34=1,50000,0)) | R34: =IF(E34="","",H34+I34+K34+L34+M34+N34+IF(O34="",0,O34)+P34+IF(Q34="",0,Q34)) | S34: =IF(E34="","",E34-(R34-I34*1.1)) | T34: =IF(E34="","",I34*1.1)
A35: 6 | B35: 2 | G35: =IF(E35="","",E35+F35) | H35: =IF(E35="","",E35*0.15) | I35: =IF(E35="","",IF(F35="",0,F35*0.13)) | J35: =IF(E35="","",H35+I35) | K35: =IF(E35="","",J35*0.1) | L35: =IF(E35="","",3000000/COUNTA(E34:E38)) | M35: =IF(E35="","",L35*0.1) | N35: =IF(E35="","",70900/COUNTA(E34:E38)) | P35: =IF(E35="","",IF(B35=1,50000,0)) | R35: =IF(E35="","",H35+I35+K35+L35+M35+N35+IF(O35="",0,O35)+P35+IF(Q35="",0,Q35)) | S35: =IF(E35="","",E35-(R35-I35*1.1)) | T35: =IF(E35="","",I35*1.1)
A36: 6 | B36: 3 | G36: =IF(E36="","",E36+F36) | H36: =IF(E36="","",E36*0.15) | I36: =IF(E36="","",IF(F36="",0,F36*0.13)) | J36: =IF(E36="","",H36+I36) | K36: =IF(E36="","",J36*0.1) | L36: =IF(E36="","",3000000/COUNTA(E34:E38)) | M36: =IF(E36="","",L36*0.1) | N36: =IF(E36="","",70900/COUNTA(E34:E38)) | P36: =IF(E36="","",IF(B36=1,50000,0)) | R36: =IF(E36="","",H36+I36+K36+L36+M36+N36+IF(O36="",0,O36)+P36+IF(Q36="",0,Q36)) | S36: =IF(E36="","",E36-(R36-I36*1.1)) | T36: =IF(E36="","",I36*1.1)
A37: 6 | B37: 4 | G37: =IF(E37="","",E37+F37) | H37: =IF(E37="","",E37*0.15) | I37: =IF(E37="","",IF(F37="",0,F37*0.13)) | J37: =IF(E37="","",H37+I37) | K37: =IF(E37="","",J37*0.1) | L37: =IF(E37="","",3000000/COUNTA(E34:E38)) | M37: =IF(E37="","",L37*0.1) | N37: =IF(E37="","",70900/COUNTA(E34:E38)) | P37: =IF(E37="","",IF(B37=1,50000,0)) | R37: =IF(E37="","",H37+I37+K37+L37+M37+N37+IF(O37="",0,O37)+P37+IF(Q37="",0,Q37)) | S37: =IF(E37="","",E37-(R37-I37*1.1)) | T37: =IF(E37="","",I37*1.1)
A38: 6 | B38: 5 | G38: =IF(E38="","",E38+F38) | H38: =IF(E38="","",E38*0.15) | I38: =IF(E38="","",IF(F38="",0,F38*0.13)) | J38: =IF(E38="","",H38+I38) | K38: =IF(E38="","",J38*0.1) | L38: =IF(E38="","",3000000/COUNTA(E34:E38)) | M38: =IF(E38="","",L38*0.1) | N38: =IF(E38="","",70900/COUNTA(E34:E38)) | P38: =IF(E38="","",IF(B38=1,50000,0)) | R38: =IF(E38="","",H38+I38+K38+L38+M38+N38+IF(O38="",0,O38)+P38+IF(Q38="",0,Q38)) | S38: =IF(E38="","",E38-(R38-I38*1.1)) | T38: =IF(E38="","",I38*1.1)
A39: 6월 | B39: 소계 | E39: =SUM(E34:E38) | F39: =SUM(F34:F38) | G39: =SUM(G34:G38) | H39: =SUM(H34:H38) | I39: =SUM(I34:I38) | J39: =SUM(J34:J38) | K39: =SUM(K34:K38) | L39: =SUM(L34:L38) | ... T39: =SUM(T34:T38)
A40: 7 | B40: 1 | G40: =IF(E40="","",E40+F40) | H40: =IF(E40="","",E40*0.15) | I40: =IF(E40="","",IF(F40="",0,F40*0.13)) | J40: =IF(E40="","",H40+I40) | K40: =IF(E40="","",J40*0.1) | L40: =IF(E40="","",3000000/COUNTA(E40:E44)) | M40: =IF(E40="","",L40*0.1) | N40: =IF(E40="","",70900/COUNTA(E40:E44)) | P40: =IF(E40="","",IF(B40=1,50000,0)) | R40: =IF(E40="","",H40+I40+K40+L40+M40+N40+IF(O40="",0,O40)+P40+IF(Q40="",0,Q40)) | S40: =IF(E40="","",E40-(R40-I40*1.1)) | T40: =IF(E40="","",I40*1.1)
...

Sheet 대시보드
A1: 미식가의 주방 — 경영 대시보드 (2026년)
M2: 현재월 → | N2: 3
B3: 이번달 총매출 | E3: 이번달 수수료수익 | H3: 이번달 임대수익 | K3: 연간 누적매출
B4: =INDEX(D9:D20,N2) | E4: =INDEX(G9:G20,N2) | H4: =INDEX(H9:H20,N2)+INDEX(I9:I20,N2) | K4: =D21
A7: 📊 월별 정산 요약
A8: 월 | B8: 카드매출 | C8: 현금매출 | D8: 총매출 | E8: 카드수수료 | F8: 현금수수료 | G8: 수수료합계 | H8: 임대료 | I8: 관리비 | J8: 공과금 | K8: 총차감 | L8: 미식가지급 | M8: 현금수령
A9: 1월 | B9: ='정산 입력'!E9 | C9: ='정산 입력'!F9 | D9: ='정산 입력'!G9 | E9: ='정산 입력'!H9 | F9: ='정산 입력'!I9 | G9: ='정산 입력'!J9 | H9: ='정산 입력'!L9 | I9: ='정산 입력'!N9 | J9: ='정산 입력'!O9 | K9: ='정산 입력'!R9 | L9: ='정산 입력'!S9 | M9: ='정산 입력'!T9
A10: 2월 | B10: ='정산 입력'!E15 | C10: ='정산 입력'!F15 | D10: ='정산 입력'!G15 | E10: ='정산 입력'!H15 | F10: ='정산 입력'!I15 | G10: ='정산 입력'!J15 | H10: ='정산 입력'!L15 | I10: ='정산 입력'!N15 | J10: ='정산 입력'!O15 | K10: ='정산 입력'!R15 | L10: ='정산 입력'!S15 | M10: ='정산 입력'!T15
A11: 3월 | B11: ='정산 입력'!E21 | C11: ='정산 입력'!F21 | D11: ='정산 입력'!G21 | E11: ='정산 입력'!H21 | F11: ='정산 입력'!I21 | G11: ='정산 입력'!J21 | H11: ='정산 입력'!L21 | I11: ='정산 입력'!N21 | J11: ='정산 입력'!O21 | K11: ='정산 입력'!R21 | L11: ='정산 입력'!S21 | M11: ='정산 입력'!T21
A12: 4월 | B12: ='정산 입력'!E27 | C12: ='정산 입력'!F27 | D12: ='정산 입력'!G27 | E12: ='정산 입력'!H27 | F12: ='정산 입력'!I27 | G12: ='정산 입력'!J27 | H12: ='정산 입력'!L27 | I12: ='정산 입력'!N27 | J12: ='정산 입력'!O27 | K12: ='정산 입력'!R27 | L12: ='정산 입력'!S27 | M12: ='정산 입력'!T27
A13: 5월 | B13: ='정산 입력'!E33 | C13: ='정산 입력'!F33 | D13: ='정산 입력'!G33 | E13: ='정산 입력'!H33 | F13: ='정산 입력'!I33 | G13: ='정산 입력'!J33 | H13: ='정산 입력'!L33 | I13: ='정산 입력'!N33 | J13: ='정산 입력'!O33 | K13: ='정산 입력'!R33 | L13: ='정산 입력'!S33 | M13: ='정산 입력'!T33
A14: 6월 | B14: ='정산 입력'!E39 | C14: ='정산 입력'!F39 | D14: ='정산 입력'!G39 | E14: ='정산 입력'!H39 | F14: ='정산 입력'!I39 | G14: ='정산 입력'!J39 | H14: ='정산 입력'!L39 | I14: ='정산 입력'!N39 | J14: ='정산 입력'!O39 | K14: ='정산 입력'!R39 | L14: ='정산 입력'!S39 | M14: ='정산 입력'!T39
A15: 7월 | B15: ='정산 입력'!E45 | C15: ='정산 입력'!F45 | D15: ='정산 입력'!G45 | E15: ='정산 입력'!H45 | F15: ='정산 입력'!I45 | G15: ='정산 입력'!J45 | H15: ='정산 입력'!L45 | I15: ='정산 입력'!N45 | J15: ='정산 입력'!O45 | K15: ='정산 입력'!R45 | L15: ='정산 입력'!S45 | M15: ='정산 입력'!T45
A16: 8월 | B16: ='정산 입력'!E51 | C16: ='정산 입력'!F51 | D16: ='정산 입력'!G51 | E16: ='정산 입력'!H51 | F16: ='정산 입력'!I51 | G16: ='정산 입력'!J51 | H16: ='정산 입력'!L51 | I16: ='정산 입력'!N51 | J16: ='정산 입력'!O51 | K16: ='정산 입력'!R51 | L16: ='정산 입력'!S51 | M16: ='정산 입력'!T51
A17: 9월 | B17: ='정산 입력'!E57 | C17: ='정산 입력'!F57 | D17: ='정산 입력'!G57 | E17: ='정산 입력'!H57 | F17: ='정산 입력'!I57 | G17: ='정산 입력'!J57 | H17: ='정산 입력'!L57 | I17: ='정산 입력'!N57 | J17: ='정산 입력'!O57 | K17: ='정산 입력'!R57 | L17: ='정산 입력'!S57 | M17: ='정산 입력'!T57
A18: 10월 | B18: ='정산 입력'!E63 | C18: ='정산 입력'!F63 | D18: ='정산 입력'!G63 | E18: ='정산 입력'!H63 | F18: ='정산 입력'!I63 | G18: ='정산 입력'!J63 | H18: ='정산 입력'!L63 | I18: ='정산 입력'!N63 | J18: ='정산 입력'!O63 | K18: ='정산 입력'!R63 | L18: ='정산 입력'!S63 | M18: ='정산 입력'!T63
A19: 11월 | B19: ='정산 입력'!E69 | C19: ='정산 입력'!F69 | D19: ='정산 입력'!G69 | E19: ='정산 입력'!H69 | F19: ='정산 입력'!I69 | G19: ='정산 입력'!J69 | H19: ='정산 입력'!L69 | I19: ='정산 입력'!N69 | J19: ='정산 입력'!O69 | K19: ='정산 입력'!R69 | L19: ='정산 입력'!S69 | M19: ='정산 입력'!T69
A20: 12월 | B20: ='정산 입력'!E75 | C20: ='정산 입력'!F75 | D20: ='정산 입력'!G75 | E20: ='정산 입력'!H75 | F20: ='정산 입력'!I75 | G20: ='정산 입력'!J75 | H20: ='정산 입력'!L75 | I20: ='정산 입력'!N75 | J20: ='정산 입력'!O75 | K20: ='정산 입력'!R75 | L20: ='정산 입력'!S75 | M20: ='정산 입력'!T75
A21: 합계 | B21: =SUM(B9:B20) | C21: =SUM(C9:C20) | D21: =SUM(D9:D20) | E21: =SUM(E9:E20) | F21: =SUM(F9:F20) | G21: =SUM(G9:G20) | H21: =SUM(H9:H20) | I21: =SUM(I9:I20) | ... M21: =SUM(M9:M20)
A40: 수익 구성 데이터
A41: 카드수수료 | B41: =E21
A42: 현금수수료 | B42: =F21
A43: 임대료 | B43: =H21
A44: 관리비 | B44: =I21
A45: 공과금 | B45: =J21

Sheet 미수금 관리
A1: 미식가의 주방 — 미수금 관리
A2: 기존 미수금 현황 + 상환 계획 (세금계산서 vs 은행거래 비교 기준)
A3: # | B3: 항목 | C3: 원금 | D3: 차감 누적 | E3: 잔액 | F3: 이자 | G3: 상태 | H3: 비고
A4: 1 | B4: 공과금 미수 | C4: 26480630 | E4: =C4-IF(D4="",0,D4) | G4: 미수 | H4: 2024.4~2025.12 누적 (가장 큰 항목)
A5: 2 | B5: 임대료 미수 | C5: 6600000 | E5: =C5-IF(D5="",0,D5) | G5: 미수
A6: 3 | B6: 현금매출 수수료 미수 | C6: 2303154 | E6: =C6-IF(D6="",0,D6) | G6: 미수
A7: 4 | B7: 관리비 미수 | C7: 2123763 | E7: =C7-IF(D7="",0,D7) | G7: 미수
A8: 5 | B8: 정수기 임대료 미수 | C8: 333900 | E8: =C8-IF(D8="",0,D8) | G8: 미수
A9: 6 | B9: 이자 (연 10%) | C9: 2766151 | E9: =C9-IF(D9="",0,D9) | G9: 미수 | H9: 지연이자율 연 10%
B10: 합계 | C10: =SUM(C4:C9) | D10: =SUM(D4:D9) | E10: =SUM(E4:E9) | F10: =SUM(F4:F9)
A12: 📋 미수금 차감 계획 (주간 정산에서 분할 차감)
A13: # | B13: 회차 | C13: 예정일 | D13: 차감금액 | E13: 차감 후 잔액 | H13: 비고
A14: 1 | B14: 1회차 | C14: 2026-03-02 | D14: 6000000 | E14: =E10-D14
A15: 2 | B15: 2회차 | C15: 2026-03-09 | D15: 6000000 | E15: =E14-D15
A16: 3 | B16: 3회차 | C16: 2026-03-16 | D16: 6000000 | E16: =E15-D16
A17: 4 | B17: 4회차 | C17: 2026-03-23 | D17: 6000000 | E17: =E16-D17
A18: 5 | B18: 5회차 | C18: 2026-03-30 | D18: 6000000 | E18: =E17-D18
A19: 6 | B19: 6회차 | C19: 2026-04-06 | D19: 6000000 | E19: =E18-D19
A20: 7 | B20: 7회차 | C20: 2026-04-20 | D20: 4607598 | E20: =E19-D20
